Workbook

Sheet FRONT
D6: IE Docket
B12: Style | E12: =+OB!C2 -> S2554MESS651WV
B13: Brand | E13: =+OB!E2 -> ADIDAS
B14: Target | E14: =+OB!K3 -> 850

Sheet COVER SHEET
B2: STARTUP PACKAGE
J3: M/P
C4: STYLE NO: | E4: =+OB!C2 -> S2554MESS651WV | G4: LINE : | J4: SEW | K4: =+OB!K76+OB!L74 -> 46.25
C5: TARGET: | E5: =+OB!K3 -> 850 | G5: UNIT: | J5: FIN | K5: =+OB!K84+OB!L84 -> 4
J6: OTH | K6: =+OB!C91+OB!C92+OB!C93 -> 4
J7: TOTAL | K7: =SUM(K4:K6) -> 54.25
C9: 1 | D9: OPERATION BREAK DOWN SEWING + FINISHING
C10: 2 | D10: BIHOURY REPORT
C11: 3 | D11: START UP DRIVE
C12: 4 | D12: TECHNICAL START UP
C13: 5 | D13: MACHINE LAYOUT
C14: 6 | D14: MACHINE REQUIREMENT PLAN
E15: PLAN INPUT : | H15: =OB!I90 -> 45955
E17: =OB!M3 -> NAZIR | J17: =OB!M4 -> SHANAKA
D18: P.M | E18: SUP | J18: IE

Sheet OB
B2: STYLE # | C2: S2554MESS651WV | E2: ADIDAS | H2: WORK MIN | I2: 600 | J2: WORK MIN | K2: 600 | L2: Date | M2: 45952
B3: TTL SMV | C3: =C85 -> 34.2 | D3: 100% Budget | E3: =+K3*C3/K2 -> 48.45 | F3: REVENUE | G3: =IF(E5="",(K3*C3*0.1),(K3*E5)) -> 2584 | H3: B/TARGET | I3: 850 | J3: L/TARGET | K3: =+I3*K4 -> 850 | L3: SUPERVISOR | M3: NAZIR
B4: OPERATOR | C4: =C89 -> 50.25 | D4: Variation | E4: =+C4-E3 -> 1.8 | F4: LINE COST | G4: =+C94*55 -> 2983.75 | H4: CATEGORY | I4: PANT | J4: EFFICIENCY | K4: 1 | L4: IE | M4: SHANAKA
B5: HELPER | C5: =C90 -> 0 | D5: CM | E5: 3.04 | F5: PROFIT/LOSS | G5: =+G3-G4 -> -399.75 | H5: B/ PCS/HEAD | I5: =+I3/(C4+C5) -> 16.915423 | J5: L/PCS/HEAD | K5: =+K3/(C4+C5) -> 16.915423
A7: SL | B7: OPERATION | C7: TIME IN | D7: TIME IN | E7: TGT/HR | F7: PLAN | G7: MACHINE | H7: WORK AIDS | I7: REQ MP | J7: ALLOTED | K7: ALLOTED | L7: ALLOTED | M7: REMARKS
C8: MIN | D8: SEC | F8: TGT/HR | H8: FOLDER/ ATTACHMENT | I8: (CAL) | J8: WP | K8: DIRECT | L8: INDIRECT
A9: BACK
A10: 1 | B10: ATTACH THREE STRIPE | C10: 0.9 | D10: =60*C10 -> 54 | E10: =IFERROR(60/C10,"") -> 66.666667 | F10: =+$K$3/($K$2/60) -> 85 | G10: KANSAI | I10: =IF(C10="","",($I$3/($I$2/60)*C10/60)) -> 1.275 | J10: =IFERROR(IF(I10<(MROUND(I10,1)+0.125),(MROUND(I10,1)),(CEILING(I10,1))),"") -> 2 | K10: =IFERROR(MROUND(I10,0.25),"") -> 1.25
A11: =+A10+1 -> 2 | B11: CHECK & TRIM THREE STRIPE | C11: 0.45 | D11: =60*C11 -> 27 | E11: =IFERROR(60/C11,"") -> 133.33333 | F11: =+$K$3/($K$2/60) -> 85 | G11: TABLE | I11: =IF(C11="","",($I$3/($I$2/60)*C11/60)) -> 0.6375 | J11: =IFERROR(IF(I11<(MROUND(I11,1)+0.125),(MROUND(I11,1)),(CEILING(I11,1))),"") -> 1 | K11: =IFERROR(MROUND(I11,0.25),"") -> 0.75
A12: =+A11+1 -> 3 | B12: JOIN BACK RISE | C12: 0.35 | D12: =60*C12 -> 21 | E12: =IFERROR(60/C12,"") -> 171.42857 | F12: =+$K$3/($K$2/60) -> 85 | G12: OL4T | I12: =IF(C12="","",($I$3/($I$2/60)*C12/60)) -> 0.49583333 | J12: =IFERROR(IF(I12<(MROUND(I12,1)+0.125),(MROUND(I12,1)),(CEILING(I12,1))),"") -> 1 | K12: =IFERROR(MROUND(I12,0.25),"") -> 0.5
A13: =+A12+1 -> 4 | B13: FUSE & CREASE BOTTOM FOR ZIPPER | C13: 0.85 | D13: =60*C13 -> 51 | E13: =IFERROR(60/C13,"") -> 70.588235 | F13: =+$K$3/($K$2/60) -> 85 | G13: IRON TABLE | I13: =IF(C13="","",($I$3/($I$2/60)*C13/60)) -> 1.2041667 | J13: =IFERROR(IF(I13<(MROUND(I13,1)+0.125),(MROUND(I13,1)),(CEILING(I13,1))),"") -> 2 | K13: =IFERROR(MROUND(I13,0.25),"") -> 1.25
A14: =+A13+1 -> 5 | B14: SERGE BOTTOM FOR LEG ZIPPER*2 | C14: 0.35 | D14: =60*C14 -> 21 | E14: =IFERROR(60/C14,"") -> 171.42857 | F14: =+$K$3/($K$2/60) -> 85 | G14: OL4T | I14: =IF(C14="","",($I$3/($I$2/60)*C14/60)) -> 0.49583333 | J14: =IFERROR(IF(I14<(MROUND(I14,1)+0.125),(MROUND(I14,1)),(CEILING(I14,1))),"") -> 1 | K14: =IFERROR(MROUND(I14,0.25),"") -> 0.5
A15: =+A14+1 -> 6 | D15: =60*C15 -> 0 | E15: =IFERROR(60/C15,"") | F15: =+$K$3/($K$2/60) -> 85 | I15: =IF(C15="","",($I$3/($I$2/60)*C15/60)) | J15: =IFERROR(IF(I15<(MROUND(I15,1)+0.125),(MROUND(I15,1)),(CEILING(I15,1))),"") | K15: =IFERROR(MROUND(I15,0.25),"")
A16: =+A15+1 -> 7 | D16: =60*C16 -> 0 | E16: =IFERROR(60/C16,"") | F16: =+$K$3/($K$2/60) -> 85 | I16: =IF(C16="","",($I$3/($I$2/60)*C16/60)) | J16: =IFERROR(IF(I16<(MROUND(I16,1)+0.125),(MROUND(I16,1)),(CEILING(I16,1))),"") | K16: =IFERROR(MROUND(I16,0.25),"")
A17: =+A16+1 -> 8 | D17: =60*C17 -> 0 | E17: =IFERROR(60/C17,"") | F17: =+$K$3/($K$2/60) -> 85 | I17: =IF(C17="","",($I$3/($I$2/60)*C17/60)) | J17: =IFERROR(IF(I17<(MROUND(I17,1)+0.125),(MROUND(I17,1)),(CEILING(I17,1))),"") | K17: =IFERROR(MROUND(I17,0.25),"")
A18: =+A22+1 -> 9 | D18: =60*C18 -> 0 | E18: =IFERROR(60/C18,"") | F18: =+$K$3/($K$2/60) -> 85 | I18: =IF(C18="","",($I$3/($I$2/60)*C18/60)) | J18: =IFERROR(IF(I18<(MROUND(I18,1)+0.125),(MROUND(I18,1)),(CEILING(I18,1))),"") | K18: =IFERROR(MROUND(I18,0.25),"")
A19: =+A14+1 -> 6 | D19: =60*C19 -> 0 | E19: =IFERROR(60/C19,"") | F19: =+$K$3/($K$2/60) -> 85 | I19: =IF(C19="","",($I$3/($I$2/60)*C19/60)) | J19: =IFERROR(IF(I19<(MROUND(I19,1)+0.125),(MROUND(I19,1)),(CEILING(I19,1))),"") | K19: =IFERROR(MROUND(I19,0.25),"")
A20: =+A19+1 -> 7 | D20: =60*C20 -> 0 | E20: =IFERROR(60/C20,"") | F20: =+$K$3/($K$2/60) -> 85 | I20: =IF(C20="","",($I$3/($I$2/60)*C20/60)) | J20: =IFERROR(IF(I20<(MROUND(I20,1)+0.125),(MROUND(I20,1)),(CEILING(I20,1))),"") | K20: =IFERROR(MROUND(I20,0.25),"")
A21: =+A17+1 -> 9 | D21: =60*C21 -> 0 | E21: =IFERROR(60/C21,"") | F21: =+$K$3/($K$2/60) -> 85 | I21: =IF(C21="","",($I$3/($I$2/60)*C21/60)) | J21: =IFERROR(IF(I21<(MROUND(I21,1)+0.125),(MROUND(I21,1)),(CEILING(I21,1))),"") | K21: =IFERROR(MROUND(I21,0.25),"")
A22: =+A16+1 -> 8 | D22: =60*C22 -> 0 | E22: =IFERROR(60/C22,"") | F22: =+$K$3/($K$2/60) -> 85 | I22: =IF(C22="","",($I$3/($I$2/60)*C22/60)) | J22: =IFERROR(IF(I22<(MROUND(I22,1)+0.125),(MROUND(I22,1)),(CEILING(I22,1))),"") | K22: =IFERROR(MROUND(I22,0.25),"")
A23: =+A21+1 -> 10 | D23: =60*C23 -> 0 | E23: =IFERROR(60/C23,"") | F23: =+$K$3/($K$2/60) -> 85 | I23: =IF(C23="","",($I$3/($I$2/60)*C23/60)) | J23: =IFERROR(IF(I23<(MROUND(I23,1)+0.125),(MROUND(I23,1)),(CEILING(I23,1))),"") | K23: =IFERROR(MROUND(I23,0.25),"")
A24: =+A23+1 -> 11 | D24: =60*C24 -> 0 | E24: =IFERROR(60/C24,"") | F24: =+$K$3/($K$2/60) -> 85 | I24: =IF(C24="","",($I$3/($I$2/60)*C24/60)) | J24: =IFERROR(IF(I24<(MROUND(I24,1)+0.125),(MROUND(I24,1)),(CEILING(I24,1))),"") | K24: =IFERROR(MROUND(I24,0.25),"")
A25: =+A24+1 -> 12 | D25: =60*C25 -> 0 | E25: =IFERROR(60/C25,"") | F25: =+$K$3/($K$2/60) -> 85 | I25: =IF(C25="","",($I$3/($I$2/60)*C25/60)) | J25: =IFERROR(IF(I25<(MROUND(I25,1)+0.125),(MROUND(I25,1)),(CEILING(I25,1))),"") | K25: =IFERROR(MROUND(I25,0.25),"")
A26: FRONT | C26: =SUM(C10:C25) -> 2.9 | I26: =SUM(I10:I25) -> 4.1083333 | J26: =SUM(J10:J25) -> 7 | K26: =SUM(K10:K25) -> 4.25 | L26: =SUM(L10:L25) -> 0
A27: =+A25+1 -> 13 | B27: FUSE & CREASE POCKET MOUTH | C27: 0.6 | D27: =60*C27 -> 36 | E27: =IFERROR(60/C27,"") -> 100 | F27: =+$K$3/($K$2/60) -> 85 | G27: IRON TABLE | I27: =IF(C27="","",($I$3/($I$2/60)*C27/60)) -> 0.85 | J27: =IFERROR(IF(I27<(MROUND(I27,1)+0.125),(MROUND(I27,1)),(CEILING(I27,1))),"") -> 1 | K27: =IFERROR(MROUND(I27,0.25),"") -> 0.75
A28: =+A27+1 -> 14 | B28: ATTACH FACING TO POCKET BAG*2 | C28: 0.35 | D28: =60*C28 -> 21 | E28: =IFERROR(60/C28,"") -> 171.42857 | F28: =+$K$3/($K$2/60) -> 85 | G28: SNLS | I28: =IF(C28="","",($I$3/($I$2/60)*C28/60)) -> 0.49583333 | J28: =IFERROR(IF(I28<(MROUND(I28,1)+0.125),(MROUND(I28,1)),(CEILING(I28,1))),"") -> 1 | K28: =IFERROR(MROUND(I28,0.25),"") -> 0.5
A29: =+A28+1 -> 15 | B29: ATTACH POCKET BAG TO FRONT | C29: 0.65 | D29: =60*C29 -> 39 | E29: =IFERROR(60/C29,"") -> 92.307692 | F29: =+$K$3/($K$2/60) -> 85 | G29: SNLS | I29: =IF(C29="","",($I$3/($I$2/60)*C29/60)) -> 0.92083333 | J29: =IFERROR(IF(I29<(MROUND(I29,1)+0.125),(MROUND(I29,1)),(CEILING(I29,1))),"") -> 1 | K29: =IFERROR(MROUND(I29,0.25),"") -> 1
A30: =+A29+1 -> 16 | B30: SHADOW STITCH POCKET MOUTH & CUT NOTCH | C30: 0.65 | D30: =60*C30 -> 39 | E30: =IFERROR(60/C30,"") -> 92.307692 | F30: =+$K$3/($K$2/60) -> 85 | G30: SNLS | I30: =IF(C30="","",($I$3/($I$2/60)*C30/60)) -> 0.92083333 | J30: =IFERROR(IF(I30<(MROUND(I30,1)+0.125),(MROUND(I30,1)),(CEILING(I30,1))),"") -> 1 | K30: =IFERROR(MROUND(I30,0.25),"") -> 1
A31: =+A30+1 -> 17 | B31: TACK INNER POCKET BAG | C31: 0.65 | D31: =60*C31 -> 39 | E31: =IFERROR(60/C31,"") -> 92.307692 | F31: =+$K$3/($K$2/60) -> 85 | G31: SNLS | I31: =IF(C31="","",($I$3/($I$2/60)*C31/60)) -> 0.92083333 | J31: =IFERROR(IF(I31<(MROUND(I31,1)+0.125),(MROUND(I31,1)),(CEILING(I31,1))),"") -> 1 | K31: =IFERROR(MROUND(I31,0.25),"") -> 1
A32: =+A31+1 -> 18 | B32: CLOSE POCKET BAG | C32: 0.65 | D32: =60*C32 -> 39 | E32: =IFERROR(60/C32,"") -> 92.307692 | F32: =+$K$3/($K$2/60) -> 85 | G32: OL4T | I32: =IF(C32="","",($I$3/($I$2/60)*C32/60)) -> 0.92083333 | J32: =IFERROR(IF(I32<(MROUND(I32,1)+0.125),(MROUND(I32,1)),(CEILING(I32,1))),"") -> 1 | K32: =IFERROR(MROUND(I32,0.25),"") -> 1
A33: =+A32+1 -> 19 | B33: POCKET BAG SIDE WAIST TACK | C33: 0.55 | D33: =60*C33 -> 33 | E33: =IFERROR(60/C33,"") -> 109.09091 | F33: =+$K$3/($K$2/60) -> 85 | G33: SNLS | I33: =IF(C33="","",($I$3/($I$2/60)*C33/60)) -> 0.77916667 | J33: =IFERROR(IF(I33<(MROUND(I33,1)+0.125),(MROUND(I33,1)),(CEILING(I33,1))),"") -> 1 | K33: =IFERROR(MROUND(I33,0.25),"") -> 0.75
A34: =+A33+1 -> 20 | B34: BARTACK POCKET*6 | C34: 0.45 | D34: =60*C34 -> 27 | E34: =IFERROR(60/C34,"") -> 133.33333 | F34: =+$K$3/($K$2/60) -> 85 | G34: BRTK | I34: =IF(C34="","",($I$3/($I$2/60)*C34/60)) -> 0.6375 | J34: =IFERROR(IF(I34<(MROUND(I34,1)+0.125),(MROUND(I34,1)),(CEILING(I34,1))),"") -> 1 | K34: =IFERROR(MROUND(I34,0.25),"") -> 0.75
A35: =+A34+1 -> 21 | B35: JOIN FRONT RISE | C35: 0.35 | D35: =60*C35 -> 21 | E35: =IFERROR(60/C35,"") -> 171.42857 | F35: =+$K$3/($K$2/60) -> 85 | G35: OL4T | I35: =IF(C35="","",($I$3/($I$2/60)*C35/60)) -> 0.49583333 | J35: =IFERROR(IF(I35<(MROUND(I35,1)+0.125),(MROUND(I35,1)),(CEILING(I35,1))),"") -> 1 | K35: =IFERROR(MROUND(I35,0.25),"") -> 0.5
A36: =+A35+1 -> 22 | D36: =60*C36 -> 0 | E36: =IFERROR(60/C36,"") | F36: =+$K$3/($K$2/60) -> 85 | I36: =IF(C36="","",($I$3/($I$2/60)*C36/60)) | J36: =IFERROR(IF(I36<(MROUND(I36,1)+0.125),(MROUND(I36,1)),(CEILING(I36,1))),"") | K36: =IFERROR(MROUND(I36,0.25),"")
A37: =+A36+1 -> 23 | D37: =60*C37 -> 0 | E37: =IFERROR(60/C37,"") | F37: =+$K$3/($K$2/60) -> 85 | I37: =IF(C37="","",($I$3/($I$2/60)*C37/60)) | J37: =IFERROR(IF(I37<(MROUND(I37,1)+0.125),(MROUND(I37,1)),(CEILING(I37,1))),"") | K37: =IFERROR(MROUND(I37,0.25),"")
A38: =+A37+1 -> 24 | D38: =60*C38 -> 0 | E38: =IFERROR(60/C38,"") | F38: =+$K$3/($K$2/60) -> 85 | I38: =IF(C38="","",($I$3/($I$2/60)*C38/60)) | J38: =IFERROR(IF(I38<(MROUND(I38,1)+0.125),(MROUND(I38,1)),(CEILING(I38,1))),"") | K38: =IFERROR(MROUND(I38,0.25),"")
A39: =+A38+1 -> 25 | D39: =60*C39 -> 0 | E39: =IFERROR(60/C39,"") | F39: =+$K$3/($K$2/60) -> 85 | I39: =IF(C39="","",($I$3/($I$2/60)*C39/60)) | J39: =IFERROR(IF(I39<(MROUND(I39,1)+0.125),(MROUND(I39,1)),(CEILING(I39,1))),"") | K39: =IFERROR(MROUND(I39,0.25),"")
A40: =+A39+1 -> 26 | D40: =60*C40 -> 0 | E40: =IFERROR(60/C40,"") | F40: =+$K$3/($K$2/60) -> 85 | I40: =IF(C40="","",($I$3/($I$2/60)*C40/60)) | J40: =IFERROR(IF(I40<(MROUND(I40,1)+0.125),(MROUND(I40,1)),(CEILING(I40,1))),"") | K40: =IFERROR(MROUND(I40,0.25),"")
A41: =+A40+1 -> 27 | D41: =60*C41 -> 0 | E41: =IFERROR(60/C41,"") | F41: =+$K$3/($K$2/60) -> 85 | I41: =IF(C41="","",($I$3/($I$2/60)*C41/60)) | J41: =IFERROR(IF(I41<(MROUND(I41,1)+0.125),(MROUND(I41,1)),(CEILING(I41,1))),"") | K41: =IFERROR(MROUND(I41,0.25),"")
A42: =+A41+1 -> 28 | D42: =60*C42 -> 0 | E42: =IFERROR(60/C42,"") | F42: =+$K$3/($K$2/60) -> 85 | I42: =IF(C42="","",($I$3/($I$2/60)*C42/60)) | J42: =IFERROR(IF(I42<(MROUND(I42,1)+0.125),(MROUND(I42,1)),(CEILING(I42,1))),"") | K42: =IFERROR(MROUND(I42,0.25),"")
...

Sheet aSC LAYOUT
A2: MACHINE LAYOUT - NEEDLE TO NEEDLE MODULE
C5: BUYER | E5: =OB!E2 -> ADIDAS | R5: INPUT DATE | V5: =OB!I90 -> 45955
C6: STYLE | E6: =OB!C2 -> S2554MESS651WV | R6: IE | V6: =OB!M4 -> SHANAKA
C7: ITEM | E7: =OB!I4 -> PANT | R7: SUPERVISOR | V7: =OB!M3 -> NAZIR
A9: OUTPUT
A14: =IFERROR(INDEX(OB!$G:$G,MATCH('aSC LAYOUT'!$B:$B,OB!$A:$A,0)),"") | B14: =+W14+1 -> 112 | C14: =IFERROR(INDEX(OB!$B:$B,MATCH('aSC LAYOUT'!$B:$B,OB!$A:$A,0)),"") | E14: =IFERROR(INDEX(OB!$C:$C,MATCH('aSC LAYOUT'!$B:$B,OB!$A:$A,0)),"") | F14: =IFERROR(INDEX(OB!$K:$K,MATCH('aSC LAYOUT'!$B:$B,OB!$A:$A,0)),"") | G14: =IF(C14="","",(MROUND(IF(E14<=0,0,60/E14),5))) | H14: =E17 -> 0 | Q14: =T17 -> 0 | R14: =IF(V14="","",(MROUND(IF(T14<=0,0,60/T14),5))) | S14: =IFERROR(INDEX(OB!$K:$K,MATCH('aSC LAYOUT'!$W:$W,OB!$A:$A,0)),"") | T14: =IFERROR(INDEX(OB!$C:$C,MATCH('aSC LAYOUT'!$W:$W,OB!$A:$A,0)),"") | V14: =IFERROR(INDEX(OB!$B:$B,MATCH('aSC LAYOUT'!$W:$W,OB!$A:$A,0)),"") | W14: =+W19+1 -> 111 | X14: =IFERROR(INDEX(OB!$G:$G,MATCH('aSC LAYOUT'!$W:$W,OB!$A:$A,0)),"")
A15: =IFERROR(INDEX(OB!$G:$G,MATCH('aSC LAYOUT'!$B:$B,OB!$A:$A,0)),"") | C15: =IFERROR(INDEX(OB!$B:$B,MATCH('aSC LAYOUT'!$B:$B,OB!$A:$A,0)),"") | E15: =IFERROR(INDEX(OB!$C:$C,MATCH('aSC LAYOUT'!$B:$B,OB!$A:$A,0)),"") | F15: =IFERROR(INDEX(OB!$K:$K,MATCH('aSC LAYOUT'!$B:$B,OB!$A:$A,0)),"") | G15: =IF(C15="","",(MROUND(IF(E15<=0,0,60/E15),5))) | I15: WS | P15: WS | R15: =IF(V15="","",(MROUND(IF(T15<=0,0,60/T15),5))) | S15: =IFERROR(INDEX(OB!$K:$K,MATCH('aSC LAYOUT'!$W:$W,OB!$A:$A,0)),"") | T15: =IFERROR(INDEX(OB!$C:$C,MATCH('aSC LAYOUT'!$W:$W,OB!$A:$A,0)),"") | V15: =IFERROR(INDEX(OB!$B:$B,MATCH('aSC LAYOUT'!$W:$W,OB!$A:$A,0)),"") | X15: =IFERROR(INDEX(OB!$G:$G,MATCH('aSC LAYOUT'!$W:$W,OB!$A:$A,0)),"")
A16: =IFERROR(INDEX(OB!$G:$G,MATCH('aSC LAYOUT'!$B:$B,OB!$A:$A,0)),"") | C16: =IFERROR(INDEX(OB!$B:$B,MATCH('aSC LAYOUT'!$B:$B,OB!$A:$A,0)),"") | E16: =IFERROR(INDEX(OB!$C:$C,MATCH('aSC LAYOUT'!$B:$B,OB!$A:$A,0)),"") | F16: =IFERROR(INDEX(OB!$K:$K,MATCH('aSC LAYOUT'!$B:$B,OB!$A:$A,0)),"") | G16: =IF(C16="","",(MROUND(IF(E16<=0,0,60/E16),5))) | H16: =F17 -> 0 | I16: =+P16+1 -> 88 | P16: =+P21+1 -> 87 | Q16: =S17 -> 0 | R16: =IF(V16="","",(MROUND(IF(T16<=0,0,60/T16),5))) | S16: =IFERROR(INDEX(OB!$K:$K,MATCH('aSC LAYOUT'!$W:$W,OB!$A:$A,0)),"") | T16: =IFERROR(INDEX(OB!$C:$C,MATCH('aSC LAYOUT'!$W:$W,OB!$A:$A,0)),"") | V16: =IFERROR(INDEX(OB!$B:$B,MATCH('aSC LAYOUT'!$W:$W,OB!$A:$A,0)),"") | X16: =IFERROR(INDEX(OB!$G:$G,MATCH('aSC LAYOUT'!$W:$W,OB!$A:$A,0)),"")
E17: =SUM(E14:E16) -> 0 | F17: =SUM(F14:F16) -> 0 | S17: =SUM(S14:S16) -> 0 | T17: =SUM(T14:T16) -> 0
A19: =IFERROR(INDEX(OB!$G:$G,MATCH('aSC LAYOUT'!$B:$B,OB!$A:$A,0)),"") | B19: =+B24+1 -> 109 | C19: =IFERROR(INDEX(OB!$B:$B,MATCH('aSC LAYOUT'!$B:$B,OB!$A:$A,0)),"") | E19: =IFERROR(INDEX(OB!$C:$C,MATCH('aSC LAYOUT'!$B:$B,OB!$A:$A,0)),"") | F19: =IFERROR(INDEX(OB!$K:$K,MATCH('aSC LAYOUT'!$B:$B,OB!$A:$A,0)),"") | G19: =IF(C19="","",(MROUND(IF(E19<=0,0,60/E19),5))) | H19: =E22 -> 0 | Q19: =T22 -> 0 | R19: =IF(V19="","",(MROUND(IF(T19<=0,0,60/T19),5))) | S19: =IFERROR(INDEX(OB!$K:$K,MATCH('aSC LAYOUT'!$W:$W,OB!$A:$A,0)),"") | T19: =IFERROR(INDEX(OB!$C:$C,MATCH('aSC LAYOUT'!$W:$W,OB!$A:$A,0)),"") | V19: =IFERROR(INDEX(OB!$B:$B,MATCH('aSC LAYOUT'!$W:$W,OB!$A:$A,0)),"") | W19: =+B19+1 -> 110 | X19: =IFERROR(INDEX(OB!$G:$G,MATCH('aSC LAYOUT'!$W:$W,OB!$A:$A,0)),"")
A20: =IFERROR(INDEX(OB!$G:$G,MATCH('aSC LAYOUT'!$B:$B,OB!$A:$A,0)),"") | C20: =IFERROR(INDEX(OB!$B:$B,MATCH('aSC LAYOUT'!$B:$B,OB!$A:$A,0)),"") | E20: =IFERROR(INDEX(OB!$C:$C,MATCH('aSC LAYOUT'!$B:$B,OB!$A:$A,0)),"") | F20: =IFERROR(INDEX(OB!$K:$K,MATCH('aSC LAYOUT'!$B:$B,OB!$A:$A,0)),"") | G20: =IF(C20="","",(MROUND(IF(E20<=0,0,60/E20),5))) | I20: WS | P20: WS | R20: =IF(V20="","",(MROUND(IF(T20<=0,0,60/T20),5))) | S20: =IFERROR(INDEX(OB!$K:$K,MATCH('aSC LAYOUT'!$W:$W,OB!$A:$A,0)),"") | T20: =IFERROR(INDEX(OB!$C:$C,MATCH('aSC LAYOUT'!$W:$W,OB!$A:$A,0)),"") | V20: =IFERROR(INDEX(OB!$B:$B,MATCH('aSC LAYOUT'!$W:$W,OB!$A:$A,0)),"") | X20: =IFERROR(INDEX(OB!$G:$G,MATCH('aSC LAYOUT'!$W:$W,OB!$A:$A,0)),"")
A21: =IFERROR(INDEX(OB!$G:$G,MATCH('aSC LAYOUT'!$B:$B,OB!$A:$A,0)),"") | C21: =IFERROR(INDEX(OB!$B:$B,MATCH('aSC LAYOUT'!$B:$B,OB!$A:$A,0)),"") | E21: =IFERROR(INDEX(OB!$C:$C,MATCH('aSC LAYOUT'!$B:$B,OB!$A:$A,0)),"") | F21: =IFERROR(INDEX(OB!$K:$K,MATCH('aSC LAYOUT'!$B:$B,OB!$A:$A,0)),"") | G21: =IF(C21="","",(MROUND(IF(E21<=0,0,60/E21),5))) | H21: =F22 -> 0 | I21: =+I26+1 -> 85 | P21: =+I21+1 -> 86 | Q21: =S22 -> 0 | R21: =IF(V21="","",(MROUND(IF(T21<=0,0,60/T21),5))) | S21: =IFERROR(INDEX(OB!$K:$K,MATCH('aSC LAYOUT'!$W:$W,OB!$A:$A,0)),"") | T21: =IFERROR(INDEX(OB!$C:$C,MATCH('aSC LAYOUT'!$W:$W,OB!$A:$A,0)),"") | V21: =IFERROR(INDEX(OB!$B:$B,MATCH('aSC LAYOUT'!$W:$W,OB!$A:$A,0)),"") | X21: =IFERROR(INDEX(OB!$G:$G,MATCH('aSC LAYOUT'!$W:$W,OB!$A:$A,0)),"")
E22: =SUM(E19:E21) -> 0 | F22: =SUM(F19:F21) -> 0 | S22: =SUM(S19:S21) -> 0 | T22: =SUM(T19:T21) -> 0
A24: =IFERROR(INDEX(OB!$G:$G,MATCH('aSC LAYOUT'!$B:$B,OB!$A:$A,0)),"") | B24: =+W24+1 -> 108 | C24: =IFERROR(INDEX(OB!$B:$B,MATCH('aSC LAYOUT'!$B:$B,OB!$A:$A,0)),"") | E24: =IFERROR(INDEX(OB!$C:$C,MATCH('aSC LAYOUT'!$B:$B,OB!$A:$A,0)),"") | F24: =IFERROR(INDEX(OB!$K:$K,MATCH('aSC LAYOUT'!$B:$B,OB!$A:$A,0)),"") | G24: =IF(C24="","",(MROUND(IF(E24<=0,0,60/E24),5))) | H24: =E27 -> 0 | Q24: =T27 -> 0 | R24: =IF(V24="","",(MROUND(IF(T24<=0,0,60/T24),5))) | S24: =IFERROR(INDEX(OB!$K:$K,MATCH('aSC LAYOUT'!$W:$W,OB!$A:$A,0)),"") | T24: =IFERROR(INDEX(OB!$C:$C,MATCH('aSC LAYOUT'!$W:$W,OB!$A:$A,0)),"") | V24: =IFERROR(INDEX(OB!$B:$B,MATCH('aSC LAYOUT'!$W:$W,OB!$A:$A,0)),"") | W24: =+W29+1 -> 107 | X24: =IFERROR(INDEX(OB!$G:$G,MATCH('aSC LAYOUT'!$W:$W,OB!$A:$A,0)),"")
A25: =IFERROR(INDEX(OB!$G:$G,MATCH('aSC LAYOUT'!$B:$B,OB!$A:$A,0)),"") | C25: =IFERROR(INDEX(OB!$B:$B,MATCH('aSC LAYOUT'!$B:$B,OB!$A:$A,0)),"") | E25: =IFERROR(INDEX(OB!$C:$C,MATCH('aSC LAYOUT'!$B:$B,OB!$A:$A,0)),"") | F25: =IFERROR(INDEX(OB!$K:$K,MATCH('aSC LAYOUT'!$B:$B,OB!$A:$A,0)),"") | G25: =IF(C25="","",(MROUND(IF(E25<=0,0,60/E25),5))) | I25: WS | P25: WS | R25: =IF(V25="","",(MROUND(IF(T25<=0,0,60/T25),5))) | S25: =IFERROR(INDEX(OB!$K:$K,MATCH('aSC LAYOUT'!$W:$W,OB!$A:$A,0)),"") | T25: =IFERROR(INDEX(OB!$C:$C,MATCH('aSC LAYOUT'!$W:$W,OB!$A:$A,0)),"") | V25: =IFERROR(INDEX(OB!$B:$B,MATCH('aSC LAYOUT'!$W:$W,OB!$A:$A,0)),"") | X25: =IFERROR(INDEX(OB!$G:$G,MATCH('aSC LAYOUT'!$W:$W,OB!$A:$A,0)),"")
A26: =IFERROR(INDEX(OB!$G:$G,MATCH('aSC LAYOUT'!$B:$B,OB!$A:$A,0)),"") | C26: =IFERROR(INDEX(OB!$B:$B,MATCH('aSC LAYOUT'!$B:$B,OB!$A:$A,0)),"") | E26: =IFERROR(INDEX(OB!$C:$C,MATCH('aSC LAYOUT'!$B:$B,OB!$A:$A,0)),"") | F26: =IFERROR(INDEX(OB!$K:$K,MATCH('aSC LAYOUT'!$B:$B,OB!$A:$A,0)),"") | G26: =IF(C26="","",(MROUND(IF(E26<=0,0,60/E26),5))) | H26: =F27 -> 0 | I26: =+P26+1 -> 84 | P26: =+P31+1 -> 83 | Q26: =S27 -> 0 | R26: =IF(V26="","",(MROUND(IF(T26<=0,0,60/T26),5))) | S26: =IFERROR(INDEX(OB!$K:$K,MATCH('aSC LAYOUT'!$W:$W,OB!$A:$A,0)),"") | T26: =IFERROR(INDEX(OB!$C:$C,MATCH('aSC LAYOUT'!$W:$W,OB!$A:$A,0)),"") | V26: =IFERROR(INDEX(OB!$B:$B,MATCH('aSC LAYOUT'!$W:$W,OB!$A:$A,0)),"") | X26: =IFERROR(INDEX(OB!$G:$G,MATCH('aSC LAYOUT'!$W:$W,OB!$A:$A,0)),"")
E27: =SUM(E24:E26) -> 0 | F27: =SUM(F24:F26) -> 0 | S27: =SUM(S24:S26) -> 0 | T27: =SUM(T24:T26) -> 0
A29: =IFERROR(INDEX(OB!$G:$G,MATCH('aSC LAYOUT'!$B:$B,OB!$A:$A,0)),"") | B29: =+B34+1 -> 105 | C29: =IFERROR(INDEX(OB!$B:$B,MATCH('aSC LAYOUT'!$B:$B,OB!$A:$A,0)),"") | E29: =IFERROR(INDEX(OB!$C:$C,MATCH('aSC LAYOUT'!$B:$B,OB!$A:$A,0)),"") | F29: =IFERROR(INDEX(OB!$K:$K,MATCH('aSC LAYOUT'!$B:$B,OB!$A:$A,0)),"") | G29: =IF(C29="","",(MROUND(IF(E29<=0,0,60/E29),5))) | H29: =E32 -> 0 | Q29: =T32 -> 0 | R29: =IF(V29="","",(MROUND(IF(T29<=0,0,60/T29),5))) | S29: =IFERROR(INDEX(OB!$K:$K,MATCH('aSC LAYOUT'!$W:$W,OB!$A:$A,0)),"") | T29: =IFERROR(INDEX(OB!$C:$C,MATCH('aSC LAYOUT'!$W:$W,OB!$A:$A,0)),"") | V29: =IFERROR(INDEX(OB!$B:$B,MATCH('aSC LAYOUT'!$W:$W,OB!$A:$A,0)),"") | W29: =+B29+1 -> 106 | X29: =IFERROR(INDEX(OB!$G:$G,MATCH('aSC LAYOUT'!$W:$W,OB!$A:$A,0)),"")
A30: =IFERROR(INDEX(OB!$G:$G,MATCH('aSC LAYOUT'!$B:$B,OB!$A:$A,0)),"") | C30: =IFERROR(INDEX(OB!$B:$B,MATCH('aSC LAYOUT'!$B:$B,OB!$A:$A,0)),"") | E30: =IFERROR(INDEX(OB!$C:$C,MATCH('aSC LAYOUT'!$B:$B,OB!$A:$A,0)),"") | F30: =IFERROR(INDEX(OB!$K:$K,MATCH('aSC LAYOUT'!$B:$B,OB!$A:$A,0)),"") | G30: =IF(C30="","",(MROUND(IF(E30<=0,0,60/E30),5))) | I30: WS | P30: WS | R30: =IF(V30="","",(MROUND(IF(T30<=0,0,60/T30),5))) | S30: =IFERROR(INDEX(OB!$K:$K,MATCH('aSC LAYOUT'!$W:$W,OB!$A:$A,0)),"") | T30: =IFERROR(INDEX(OB!$C:$C,MATCH('aSC LAYOUT'!$W:$W,OB!$A:$A,0)),"") | V30: =IFERROR(INDEX(OB!$B:$B,MATCH('aSC LAYOUT'!$W:$W,OB!$A:$A,0)),"") | X30: =IFERROR(INDEX(OB!$G:$G,MATCH('aSC LAYOUT'!$W:$W,OB!$A:$A,0)),"")
A31: =IFERROR(INDEX(OB!$G:$G,MATCH('aSC LAYOUT'!$B:$B,OB!$A:$A,0)),"") | C31: =IFERROR(INDEX(OB!$B:$B,MATCH('aSC LAYOUT'!$B:$B,OB!$A:$A,0)),"") | E31: =IFERROR(INDEX(OB!$C:$C,MATCH('aSC LAYOUT'!$B:$B,OB!$A:$A,0)),"") | F31: =IFERROR(INDEX(OB!$K:$K,MATCH('aSC LAYOUT'!$B:$B,OB!$A:$A,0)),"") | G31: =IF(C31="","",(MROUND(IF(E31<=0,0,60/E31),5))) | H31: =F32 -> 0 | I31: =+I36+1 -> 81 | P31: =+I31+1 -> 82 | Q31: =S32 -> 0 | R31: =IF(V31="","",(MROUND(IF(T31<=0,0,60/T31),5))) | S31: =IFERROR(INDEX(OB!$K:$K,MATCH('aSC LAYOUT'!$W:$W,OB!$A:$A,0)),"") | T31: =IFERROR(INDEX(OB!$C:$C,MATCH('aSC LAYOUT'!$W:$W,OB!$A:$A,0)),"") | V31: =IFERROR(INDEX(OB!$B:$B,MATCH('aSC LAYOUT'!$W:$W,OB!$A:$A,0)),"") | X31: =IFERROR(INDEX(OB!$G:$G,MATCH('aSC LAYOUT'!$W:$W,OB!$A:$A,0)),"")
E32: =SUM(E29:E31) -> 0 | F32: =SUM(F29:F31) -> 0 | S32: =SUM(S29:S31) -> 0 | T32: =SUM(T29:T31) -> 0
A34: =IFERROR(INDEX(OB!$G:$G,MATCH('aSC LAYOUT'!$B:$B,OB!$A:$A,0)),"") | B34: =+W34+1 -> 104 | C34: =IFERROR(INDEX(OB!$B:$B,MATCH('aSC LAYOUT'!$B:$B,OB!$A:$A,0)),"") | E34: =IFERROR(INDEX(OB!$C:$C,MATCH('aSC LAYOUT'!$B:$B,OB!$A:$A,0)),"") | F34: =IFERROR(INDEX(OB!$K:$K,MATCH('aSC LAYOUT'!$B:$B,OB!$A:$A,0)),"") | G34: =IF(C34="","",(MROUND(IF(E34<=0,0,60/E34),5))) | H34: =E37 -> 0 | Q34: =T37 -> 0 | R34: =IF(V34="","",(MROUND(IF(T34<=0,0,60/T34),5))) | S34: =IFERROR(INDEX(OB!$K:$K,MATCH('aSC LAYOUT'!$W:$W,OB!$A:$A,0)),"") | T34: =IFERROR(INDEX(OB!$C:$C,MATCH('aSC LAYOUT'!$W:$W,OB!$A:$A,0)),"") | V34: =IFERROR(INDEX(OB!$B:$B,MATCH('aSC LAYOUT'!$W:$W,OB!$A:$A,0)),"") | W34: =+W39+1 -> 103 | X34: =IFERROR(INDEX(OB!$G:$G,MATCH('aSC LAYOUT'!$W:$W,OB!$A:$A,0)),"")
A35: =IFERROR(INDEX(OB!$G:$G,MATCH('aSC LAYOUT'!$B:$B,OB!$A:$A,0)),"") | C35: =IFERROR(INDEX(OB!$B:$B,MATCH('aSC LAYOUT'!$B:$B,OB!$A:$A,0)),"") | E35: =IFERROR(INDEX(OB!$C:$C,MATCH('aSC LAYOUT'!$B:$B,OB!$A:$A,0)),"") | F35: =IFERROR(INDEX(OB!$K:$K,MATCH('aSC LAYOUT'!$B:$B,OB!$A:$A,0)),"") | G35: =IF(C35="","",(MROUND(IF(E35<=0,0,60/E35),5))) | I35: WS | P35: WS | R35: =IF(V35="","",(MROUND(IF(T35<=0,0,60/T35),5))) | S35: =IFERROR(INDEX(OB!$K:$K,MATCH('aSC LAYOUT'!$W:$W,OB!$A:$A,0)),"") | T35: =IFERROR(INDEX(OB!$C:$C,MATCH('aSC LAYOUT'!$W:$W,OB!$A:$A,0)),"") | V35: =IFERROR(INDEX(OB!$B:$B,MATCH('aSC LAYOUT'!$W:$W,OB!$A:$A,0)),"") | X35: =IFERROR(INDEX(OB!$G:$G,MATCH('aSC LAYOUT'!$W:$W,OB!$A:$A,0)),"")
A36: =IFERROR(INDEX(OB!$G:$G,MATCH('aSC LAYOUT'!$B:$B,OB!$A:$A,0)),"") | C36: =IFERROR(INDEX(OB!$B:$B,MATCH('aSC LAYOUT'!$B:$B,OB!$A:$A,0)),"") | E36: =IFERROR(INDEX(OB!$C:$C,MATCH('aSC LAYOUT'!$B:$B,OB!$A:$A,0)),"") | F36: =IFERROR(INDEX(OB!$K:$K,MATCH('aSC LAYOUT'!$B:$B,OB!$A:$A,0)),"") | G36: =IF(C36="","",(MROUND(IF(E36<=0,0,60/E36),5))) | H36: =F37 -> 0 | I36: =+P36+1 -> 80 | P36: =+P41+1 -> 79 | Q36: =S37 -> 0 | R36: =IF(V36="","",(MROUND(IF(T36<=0,0,60/T36),5))) | S36: =IFERROR(INDEX(OB!$K:$K,MATCH('aSC LAYOUT'!$W:$W,OB!$A:$A,0)),"") | T36: =IFERROR(INDEX(OB!$C:$C,MATCH('aSC LAYOUT'!$W:$W,OB!$A:$A,0)),"") | V36: =IFERROR(INDEX(OB!$B:$B,MATCH('aSC LAYOUT'!$W:$W,OB!$A:$A,0)),"") | X36: =IFERROR(INDEX(OB!$G:$G,MATCH('aSC LAYOUT'!$W:$W,OB!$A:$A,0)),"")
E37: =SUM(E34:E36) -> 0 | F37: =SUM(F34:F36) -> 0 | S37: =SUM(S34:S36) -> 0 | T37: =SUM(T34:T36) -> 0
A39: =IFERROR(INDEX(OB!$G:$G,MATCH('aSC LAYOUT'!$B:$B,OB!$A:$A,0)),"") | B39: =+B44+1 -> 101 | C39: =IFERROR(INDEX(OB!$B:$B,MATCH('aSC LAYOUT'!$B:$B,OB!$A:$A,0)),"") | E39: =IFERROR(INDEX(OB!$C:$C,MATCH('aSC LAYOUT'!$B:$B,OB!$A:$A,0)),"") | F39: =IFERROR(INDEX(OB!$K:$K,MATCH('aSC LAYOUT'!$B:$B,OB!$A:$A,0)),"") | G39: =IF(C39="","",(MROUND(IF(E39<=0,0,60/E39),5))) | H39: =E42 -> 0 | Q39: =T42 -> 0 | R39: =IF(V39="","",(MROUND(IF(T39<=0,0,60/T39),5))) | S39: =IFERROR(INDEX(OB!$K:$K,MATCH('aSC LAYOUT'!$W:$W,OB!$A:$A,0)),"") | T39: =IFERROR(INDEX(OB!$C:$C,MATCH('aSC LAYOUT'!$W:$W,OB!$A:$A,0)),"") | V39: =IFERROR(INDEX(OB!$B:$B,MATCH('aSC LAYOUT'!$W:$W,OB!$A:$A,0)),"") | W39: =+B39+1 -> 102 | X39: =IFERROR(INDEX(OB!$G:$G,MATCH('aSC LAYOUT'!$W:$W,OB!$A:$A,0)),"")
A40: =IFERROR(INDEX(OB!$G:$G,MATCH('aSC LAYOUT'!$B:$B,OB!$A:$A,0)),"") | C40: =IFERROR(INDEX(OB!$B:$B,MATCH('aSC LAYOUT'!$B:$B,OB!$A:$A,0)),"") | E40: =IFERROR(INDEX(OB!$C:$C,MATCH('aSC LAYOUT'!$B:$B,OB!$A:$A,0)),"") | F40: =IFERROR(INDEX(OB!$K:$K,MATCH('aSC LAYOUT'!$B:$B,OB!$A:$A,0)),"") | G40: =IF(C40="","",(MROUND(IF(E40<=0,0,60/E40),5))) | I40: WS | P40: WS | R40: =IF(V40="","",(MROUND(IF(T40<=0,0,60/T40),5))) | S40: =IFERROR(INDEX(OB!$K:$K,MATCH('aSC LAYOUT'!$W:$W,OB!$A:$A,0)),"") | T40: =IFERROR(INDEX(OB!$C:$C,MATCH('aSC LAYOUT'!$W:$W,OB!$A:$A,0)),"") | V40: =IFERROR(INDEX(OB!$B:$B,MATCH('aSC LAYOUT'!$W:$W,OB!$A:$A,0)),"") | X40: =IFERROR(INDEX(OB!$G:$G,MATCH('aSC LAYOUT'!$W:$W,OB!$A:$A,0)),"")
A41: =IFERROR(INDEX(OB!$G:$G,MATCH('aSC LAYOUT'!$B:$B,OB!$A:$A,0)),"") | C41: =IFERROR(INDEX(OB!$B:$B,MATCH('aSC LAYOUT'!$B:$B,OB!$A:$A,0)),"") | E41: =IFERROR(INDEX(OB!$C:$C,MATCH('aSC LAYOUT'!$B:$B,OB!$A:$A,0)),"") | F41: =IFERROR(INDEX(OB!$K:$K,MATCH('aSC LAYOUT'!$B:$B,OB!$A:$A,0)),"") | G41: =IF(C41="","",(MROUND(IF(E41<=0,0,60/E41),5))) | H41: =F42 -> 0 | I41: =+I46+1 -> 77 | P41: =+I41+1 -> 78 | Q41: =S42 -> 0 | R41: =IF(V41="","",(MROUND(IF(T41<=0,0,60/T41),5))) | S41: =IFERROR(INDEX(OB!$K:$K,MATCH('aSC LAYOUT'!$W:$W,OB!$A:$A,0)),"") | T41: =IFERROR(INDEX(OB!$C:$C,MATCH('aSC LAYOUT'!$W:$W,OB!$A:$A,0)),"") | V41: =IFERROR(INDEX(OB!$B:$B,MATCH('aSC LAYOUT'!$W:$W,OB!$A:$A,0)),"") | X41: =IFERROR(INDEX(OB!$G:$G,MATCH('aSC LAYOUT'!$W:$W,OB!$A:$A,0)),"")
E42: =SUM(E39:E41) -> 0 | F42: =SUM(F39:F41) -> 0 | S42: =SUM(S39:S41) -> 0 | T42: =SUM(T39:T41) -> 0
A44: =IFERROR(INDEX(OB!$G:$G,MATCH('aSC LAYOUT'!$B:$B,OB!$A:$A,0)),"") | B44: =+W44+1 -> 100 | C44: =IFERROR(INDEX(OB!$B:$B,MATCH('aSC LAYOUT'!$B:$B,OB!$A:$A,0)),"") | E44: =IFERROR(INDEX(OB!$C:$C,MATCH('aSC LAYOUT'!$B:$B,OB!$A:$A,0)),"") | F44: =IFERROR(INDEX(OB!$K:$K,MATCH('aSC LAYOUT'!$B:$B,OB!$A:$A,0)),"") | G44: =IF(C44="","",(MROUND(IF(E44<=0,0,60/E44),5))) | H44: =E47 -> 0 | Q44: =T47 -> 0 | R44: =IF(V44="","",(MROUND(IF(T44<=0,0,60/T44),5))) | S44: =IFERROR(INDEX(OB!$K:$K,MATCH('aSC LAYOUT'!$W:$W,OB!$A:$A,0)),"") | T44: =IFERROR(INDEX(OB!$C:$C,MATCH('aSC LAYOUT'!$W:$W,OB!$A:$A,0)),"") | V44: =IFERROR(INDEX(OB!$B:$B,MATCH('aSC LAYOUT'!$W:$W,OB!$A:$A,0)),"") | W44: =+W49+1 -> 99 | X44: =IFERROR(INDEX(OB!$G:$G,MATCH('aSC LAYOUT'!$W:$W,OB!$A:$A,0)),"")
A45: =IFERROR(INDEX(OB!$G:$G,MATCH('aSC LAYOUT'!$B:$B,OB!$A:$A,0)),"") | C45: =IFERROR(INDEX(OB!$B:$B,MATCH('aSC LAYOUT'!$B:$B,OB!$A:$A,0)),"") | E45: =IFERROR(INDEX(OB!$C:$C,MATCH('aSC LAYOUT'!$B:$B,OB!$A:$A,0)),"") | F45: =IFERROR(INDEX(OB!$K:$K,MATCH('aSC LAYOUT'!$B:$B,OB!$A:$A,0)),"") | G45: =IF(C45="","",(MROUND(IF(E45<=0,0,60/E45),5))) | I45: WS | P45: WS | R45: =IF(V45="","",(MROUND(IF(T45<=0,0,60/T45),5))) | S45: =IFERROR(INDEX(OB!$K:$K,MATCH('aSC LAYOUT'!$W:$W,OB!$A:$A,0)),"") | T45: =IFERROR(INDEX(OB!$C:$C,MATCH('aSC LAYOUT'!$W:$W,OB!$A:$A,0)),"") | V45: =IFERROR(INDEX(OB!$B:$B,MATCH('aSC LAYOUT'!$W:$W,OB!$A:$A,0)),"") | X45: =IFERROR(INDEX(OB!$G:$G,MATCH('aSC LAYOUT'!$W:$W,OB!$A:$A,0)),"")
A46: =IFERROR(INDEX(OB!$G:$G,MATCH('aSC LAYOUT'!$B:$B,OB!$A:$A,0)),"") | C46: =IFERROR(INDEX(OB!$B:$B,MATCH('aSC LAYOUT'!$B:$B,OB!$A:$A,0)),"") | E46: =IFERROR(INDEX(OB!$C:$C,MATCH('aSC LAYOUT'!$B:$B,OB!$A:$A,0)),"") | F46: =IFERROR(INDEX(OB!$K:$K,MATCH('aSC LAYOUT'!$B:$B,OB!$A:$A,0)),"") | G46: =IF(C46="","",(MROUND(IF(E46<=0,0,60/E46),5))) | H46: =F47 -> 0 | I46: =+P46+1 -> 76 | P46: =+P51+1 -> 75 | Q46: =S47 -> 0 | R46: =IF(V46="","",(MROUND(IF(T46<=0,0,60/T46),5))) | S46: =IFERROR(INDEX(OB!$K:$K,MATCH('aSC LAYOUT'!$W:$W,OB!$A:$A,0)),"") | T46: =IFERROR(INDEX(OB!$C:$C,MATCH('aSC LAYOUT'!$W:$W,OB!$A:$A,0)),"") | V46: =IFERROR(INDEX(OB!$B:$B,MATCH('aSC LAYOUT'!$W:$W,OB!$A:$A,0)),"") | X46: =IFERROR(INDEX(OB!$G:$G,MATCH('aSC LAYOUT'!$W:$W,OB!$A:$A,0)),"")
E47: =SUM(E44:E46) -> 0 | F47: =SUM(F44:F46) -> 0 | S47: =SUM(S44:S46) -> 0 | T47: =SUM(T44:T46) -> 0
A49: =IFERROR(INDEX(OB!$G:$G,MATCH('aSC LAYOUT'!$B:$B,OB!$A:$A,0)),"") | B49: =+B54+1 -> 97 | C49: =IFERROR(INDEX(OB!$B:$B,MATCH('aSC LAYOUT'!$B:$B,OB!$A:$A,0)),"") | E49: =IFERROR(INDEX(OB!$C:$C,MATCH('aSC LAYOUT'!$B:$B,OB!$A:$A,0)),"") | F49: =IFERROR(INDEX(OB!$K:$K,MATCH('aSC LAYOUT'!$B:$B,OB!$A:$A,0)),"") | G49: =IF(C49="","",(MROUND(IF(E49<=0,0,60/E49),5))) | H49: =E52 -> 0 | Q49: =T52 -> 0 | R49: =IF(V49="","",(MROUND(IF(T49<=0,0,60/T49),5))) | S49: =IFERROR(INDEX(OB!$K:$K,MATCH('aSC LAYOUT'!$W:$W,OB!$A:$A,0)),"") | T49: =IFERROR(INDEX(OB!$C:$C,MATCH('aSC LAYOUT'!$W:$W,OB!$A:$A,0)),"") | V49: =IFERROR(INDEX(OB!$B:$B,MATCH('aSC LAYOUT'!$W:$W,OB!$A:$A,0)),"") | W49: =+B49+1 -> 98 | X49: =IFERROR(INDEX(OB!$G:$G,MATCH('aSC LAYOUT'!$W:$W,OB!$A:$A,0)),"")
A50: =IFERROR(INDEX(OB!$G:$G,MATCH('aSC LAYOUT'!$B:$B,OB!$A:$A,0)),"") | C50: =IFERROR(INDEX(OB!$B:$B,MATCH('aSC LAYOUT'!$B:$B,OB!$A:$A,0)),"") | E50: =IFERROR(INDEX(OB!$C:$C,MATCH('aSC LAYOUT'!$B:$B,OB!$A:$A,0)),"") | F50: =IFERROR(INDEX(OB!$K:$K,MATCH('aSC LAYOUT'!$B:$B,OB!$A:$A,0)),"") | G50: =IF(C50="","",(MROUND(IF(E50<=0,0,60/E50),5))) | I50: WS | P50: WS | R50: =IF(V50="","",(MROUND(IF(T50<=0,0,60/T50),5))) | S50: =IFERROR(INDEX(OB!$K:$K,MATCH('aSC LAYOUT'!$W:$W,OB!$A:$A,0)),"") | T50: =IFERROR(INDEX(OB!$C:$C,MATCH('aSC LAYOUT'!$W:$W,OB!$A:$A,0)),"") | V50: =IFERROR(INDEX(OB!$B:$B,MATCH('aSC LAYOUT'!$W:$W,OB!$A:$A,0)),"") | X50: =IFERROR(INDEX(OB!$G:$G,MATCH('aSC LAYOUT'!$W:$W,OB!$A:$A,0)),"")
A51: =IFERROR(INDEX(OB!$G:$G,MATCH('aSC LAYOUT'!$B:$B,OB!$A:$A,0)),"") | C51: =IFERROR(INDEX(OB!$B:$B,MATCH('aSC LAYOUT'!$B:$B,OB!$A:$A,0)),"") | E51: =IFERROR(INDEX(OB!$C:$C,MATCH('aSC LAYOUT'!$B:$B,OB!$A:$A,0)),"") | F51: =IFERROR(INDEX(OB!$K:$K,MATCH('aSC LAYOUT'!$B:$B,OB!$A:$A,0)),"") | G51: =IF(C51="","",(MROUND(IF(E51<=0,0,60/E51),5))) | H51: =F52 -> 0 | I51: =+I56+1 -> 73 | P51: =+I51+1 -> 74 | Q51: =S52 -> 0 | R51: =IF(V51="","",(MROUND(IF(T51<=0,0,60/T51),5))) | S51: =IFERROR(INDEX(OB!$K:$K,MATCH('aSC LAYOUT'!$W:$W,OB!$A:$A,0)),"") | T51: =IFERROR(INDEX(OB!$C:$C,MATCH('aSC LAYOUT'!$W:$W,OB!$A:$A,0)),"") | V51: =IFERROR(INDEX(OB!$B:$B,MATCH('aSC LAYOUT'!$W:$W,OB!$A:$A,0)),"") | X51: =IFERROR(INDEX(OB!$G:$G,MATCH('aSC LAYOUT'!$W:$W,OB!$A:$A,0)),"")
E52: =SUM(E49:E51) -> 0 | F52: =SUM(F49:F51) -> 0 | S52: =SUM(S49:S51) -> 0 | T52: =SUM(T49:T51) -> 0
A54: =IFERROR(INDEX(OB!$G:$G,MATCH('aSC LAYOUT'!$B:$B,OB!$A:$A,0)),"") | B54: =+W54+1 -> 96 | C54: =IFERROR(INDEX(OB!$B:$B,MATCH('aSC LAYOUT'!$B:$B,OB!$A:$A,0)),"") | E54: =IFERROR(INDEX(OB!$C:$C,MATCH('aSC LAYOUT'!$B:$B,OB!$A:$A,0)),"") | F54: =IFERROR(INDEX(OB!$K:$K,MATCH('aSC LAYOUT'!$B:$B,OB!$A:$A,0)),"") | G54: =IF(C54="","",(MROUND(IF(E54<=0,0,60/E54),5))) | H54: =E57 -> 0 | Q54: =T57 -> 0 | R54: =IF(V54="","",(MROUND(IF(T54<=0,0,60/T54),5))) | S54: =IFERROR(INDEX(OB!$K:$K,MATCH('aSC LAYOUT'!$W:$W,OB!$A:$A,0)),"") | T54: =IFERROR(INDEX(OB!$C:$C,MATCH('aSC LAYOUT'!$W:$W,OB!$A:$A,0)),"") | V54: =IFERROR(INDEX(OB!$B:$B,MATCH('aSC LAYOUT'!$W:$W,OB!$A:$A,0)),"") | W54: =+W59+1 -> 95 | X54: =IFERROR(INDEX(OB!$G:$G,MATCH('aSC LAYOUT'!$W:$W,OB!$A:$A,0)),"")
A55: =IFERROR(INDEX(OB!$G:$G,MATCH('aSC LAYOUT'!$B:$B,OB!$A:$A,0)),"") | C55: =IFERROR(INDEX(OB!$B:$B,MATCH('aSC LAYOUT'!$B:$B,OB!$A:$A,0)),"") | E55: =IFERROR(INDEX(OB!$C:$C,MATCH('aSC LAYOUT'!$B:$B,OB!$A:$A,0)),"") | F55: =IFERROR(INDEX(OB!$K:$K,MATCH('aSC LAYOUT'!$B:$B,OB!$A:$A,0)),"") | G55: =IF(C55="","",(MROUND(IF(E55<=0,0,60/E55),5))) | I55: WS | P55: WS | R55: =IF(V55="","",(MROUND(IF(T55<=0,0,60/T55),5))) | S55: =IFERROR(INDEX(OB!$K:$K,MATCH('aSC LAYOUT'!$W:$W,OB!$A:$A,0)),"") | T55: =IFERROR(INDEX(OB!$C:$C,MATCH('aSC LAYOUT'!$W:$W,OB!$A:$A,0)),"") | V55: =IFERROR(INDEX(OB!$B:$B,MATCH('aSC LAYOUT'!$W:$W,OB!$A:$A,0)),"") | X55: =IFERROR(INDEX(OB!$G:$G,MATCH('aSC LAYOUT'!$W:$W,OB!$A:$A,0)),"")
A56: =IFERROR(INDEX(OB!$G:$G,MATCH('aSC LAYOUT'!$B:$B,OB!$A:$A,0)),"") | C56: =IFERROR(INDEX(OB!$B:$B,MATCH('aSC LAYOUT'!$B:$B,OB!$A:$A,0)),"") | E56: =IFERROR(INDEX(OB!$C:$C,MATCH('aSC LAYOUT'!$B:$B,OB!$A:$A,0)),"") | F56: =IFERROR(INDEX(OB!$K:$K,MATCH('aSC LAYOUT'!$B:$B,OB!$A:$A,0)),"") | G56: =IF(C56="","",(MROUND(IF(E56<=0,0,60/E56),5))) | H56: =F57 -> 0 | I56: =+P56+1 -> 72 | P56: =+P61+1 -> 71 | Q56: =S57 -> 0 | R56: =IF(V56="","",(MROUND(IF(T56<=0,0,60/T56),5))) | S56: =IFERROR(INDEX(OB!$K:$K,MATCH('aSC LAYOUT'!$W:$W,OB!$A:$A,0)),"") | T56: =IFERROR(INDEX(OB!$C:$C,MATCH('aSC LAYOUT'!$W:$W,OB!$A:$A,0)),"") | V56: =IFERROR(INDEX(OB!$B:$B,MATCH('aSC LAYOUT'!$W:$W,OB!$A:$A,0)),"") | X56: =IFERROR(INDEX(OB!$G:$G,MATCH('aSC LAYOUT'!$W:$W,OB!$A:$A,0)),"")
...

Sheet BIHOURLY 
A1: SIDNEY APPARELS L.L.C. , AQABA
A2: STYLE NO | C2: =+OB!C2 -> S2554MESS651WV | D2: LINE: - S-24 | E2: Bihourly
C3: TARGET: | D3: 1000 | I3: NAME: | K3: =OB!M3 -> NAZIR
A4: S NO | B4: OPERATION | C4: OPERATOR | D4: M/C | E4: M/P | F4: BI-HRLY TARGET | G4: Op. WIP | H4: 7.3-9.3 | I4: 9.3-11.45 | J4: 11.45-1.45 | K4: 1.45-4 | L4: 4-6.15
A5: 1 | B5: =IFERROR(INDEX(OB!B:B,MATCH('BIHOURLY '!A:A,OB!A:A,0)),"") -> ATTACH THREE STRIPE | C5: HAJERA | D5: =IFERROR(INDEX(OB!G:G,MATCH('BIHOURLY '!A:A,OB!A:A,0)),"") -> KANSAI | E5: 2 | F5: 100
C6: NAJMOON | F6: 100
A8: =+A5+1 -> 2 | B8: =IFERROR(INDEX(OB!B:B,MATCH('BIHOURLY '!A:A,OB!A:A,0)),"") -> CHECK & TRIM THREE STRIPE | C8: KATHIJA | D8: IRON TABLE | E8: 1 | F8: 200
A10: =+A8+1 -> 3 | B10: =IFERROR(INDEX(OB!B:B,MATCH('BIHOURLY '!A:A,OB!A:A,0)),"") -> JOIN BACK RISE | D10: =IFERROR(INDEX(OB!G:G,MATCH('BIHOURLY '!A:A,OB!A:A,0)),"") -> OL4T | E10: =IFERROR(INDEX(OB!K:K,MATCH('BIHOURLY '!A:A,OB!A:A,0)),"") -> 0.5 | F10: =IFERROR((OB!$K$3/'BIHOURLY '!E10)/5,"") -> 340
A12: =+A10+1 -> 4 | B12: =IFERROR(INDEX(OB!B:B,MATCH('BIHOURLY '!A:A,OB!A:A,0)),"") -> FUSE & CREASE BOTTOM FOR ZIPPER | D12: =IFERROR(INDEX(OB!G:G,MATCH('BIHOURLY '!A:A,OB!A:A,0)),"") -> IRON TABLE | E12: =IFERROR(INDEX(OB!K:K,MATCH('BIHOURLY '!A:A,OB!A:A,0)),"") -> 1.25 | F12: =IFERROR((OB!$K$3/'BIHOURLY '!E12)/5,"") -> 136
A14: =+A12+1 -> 5 | B14: =IFERROR(INDEX(OB!B:B,MATCH('BIHOURLY '!A:A,OB!A:A,0)),"") -> SERGE BOTTOM FOR LEG ZIPPER*2 | D14: =IFERROR(INDEX(OB!G:G,MATCH('BIHOURLY '!A:A,OB!A:A,0)),"") -> OL4T | E14: =IFERROR(INDEX(OB!K:K,MATCH('BIHOURLY '!A:A,OB!A:A,0)),"") -> 0.5 | F14: =IFERROR((OB!$K$3/'BIHOURLY '!E14)/5,"") -> 340
A16: =+A14+1 -> 6 | B16: =IFERROR(INDEX(OB!B:B,MATCH('BIHOURLY '!A:A,OB!A:A,0)),"") -> 0 | D16: =IFERROR(INDEX(OB!G:G,MATCH('BIHOURLY '!A:A,OB!A:A,0)),"") -> 0 | E16: =IFERROR(INDEX(OB!K:K,MATCH('BIHOURLY '!A:A,OB!A:A,0)),"") | F16: =IFERROR((OB!$K$3/'BIHOURLY '!E16)/5,"")
A18: =+A16+1 -> 7 | B18: =IFERROR(INDEX(OB!B:B,MATCH('BIHOURLY '!A:A,OB!A:A,0)),"") -> 0 | D18: =IFERROR(INDEX(OB!G:G,MATCH('BIHOURLY '!A:A,OB!A:A,0)),"") -> 0 | E18: =IFERROR(INDEX(OB!K:K,MATCH('BIHOURLY '!A:A,OB!A:A,0)),"") | F18: =IFERROR((OB!$K$3/'BIHOURLY '!E18)/5,"")
A20: =+A18+1 -> 8 | B20: =IFERROR(INDEX(OB!B:B,MATCH('BIHOURLY '!A:A,OB!A:A,0)),"") -> 0 | D20: =IFERROR(INDEX(OB!G:G,MATCH('BIHOURLY '!A:A,OB!A:A,0)),"") -> 0 | E20: =IFERROR(INDEX(OB!K:K,MATCH('BIHOURLY '!A:A,OB!A:A,0)),"") | F20: =IFERROR((OB!$K$3/'BIHOURLY '!E20)/5,"")
A22: =+A20+1 -> 9 | B22: =IFERROR(INDEX(OB!B:B,MATCH('BIHOURLY '!A:A,OB!A:A,0)),"") -> 0 | D22: =IFERROR(INDEX(OB!G:G,MATCH('BIHOURLY '!A:A,OB!A:A,0)),"") -> 0 | E22: =IFERROR(INDEX(OB!K:K,MATCH('BIHOURLY '!A:A,OB!A:A,0)),"") | F22: =IFERROR((OB!$K$3/'BIHOURLY '!E22)/5,"")
A24: =+A22+1 -> 10 | B24: =IFERROR(INDEX(OB!B:B,MATCH('BIHOURLY '!A:A,OB!A:A,0)),"") -> 0 | D24: =IFERROR(INDEX(OB!G:G,MATCH('BIHOURLY '!A:A,OB!A:A,0)),"") -> 0 | E24: =IFERROR(INDEX(OB!K:K,MATCH('BIHOURLY '!A:A,OB!A:A,0)),"") | F24: =IFERROR((OB!$K$3/'BIHOURLY '!E24)/5,"")
A26: =+A24+1 -> 11 | B26: =IFERROR(INDEX(OB!B:B,MATCH('BIHOURLY '!A:A,OB!A:A,0)),"") -> 0 | D26: =IFERROR(INDEX(OB!G:G,MATCH('BIHOURLY '!A:A,OB!A:A,0)),"") -> 0 | E26: =IFERROR(INDEX(OB!K:K,MATCH('BIHOURLY '!A:A,OB!A:A,0)),"") | F26: =IFERROR((OB!$K$3/'BIHOURLY '!E26)/5,"")
A28: =+A26+1 -> 12 | B28: =IFERROR(INDEX(OB!B:B,MATCH('BIHOURLY '!A:A,OB!A:A,0)),"") -> 0 | D28: =IFERROR(INDEX(OB!G:G,MATCH('BIHOURLY '!A:A,OB!A:A,0)),"") -> 0 | E28: =IFERROR(INDEX(OB!K:K,MATCH('BIHOURLY '!A:A,OB!A:A,0)),"") | F28: =IFERROR((OB!$K$3/'BIHOURLY '!E28)/5,"")
A31: =+A28+1 -> 13 | B31: =IFERROR(INDEX(OB!B:B,MATCH('BIHOURLY '!A:A,OB!A:A,0)),"") -> FUSE & CREASE POCKET MOUTH | C31: JANISH | D31: =IFERROR(INDEX(OB!G:G,MATCH('BIHOURLY '!A:A,OB!A:A,0)),"") -> IRON TABLE | E31: 1 | F31: 200
A33: =+A31+1 -> 14 | B33: =IFERROR(INDEX(OB!B:B,MATCH('BIHOURLY '!A:A,OB!A:A,0)),"") -> ATTACH FACING TO POCKET BAG*2 | C33: SUMI | D33: =IFERROR(INDEX(OB!G:G,MATCH('BIHOURLY '!A:A,OB!A:A,0)),"") -> SNLS | E33: 1 | F33: 200
A35: =+A33+1 -> 15 | B35: =IFERROR(INDEX(OB!B:B,MATCH('BIHOURLY '!A:A,OB!A:A,0)),"") -> ATTACH POCKET BAG TO FRONT | C35: SHAHIDA | D35: =IFERROR(INDEX(OB!G:G,MATCH('BIHOURLY '!A:A,OB!A:A,0)),"") -> SNLS | E35: =IFERROR(INDEX(OB!K:K,MATCH('BIHOURLY '!A:A,OB!A:A,0)),"") -> 1 | F35: 200
B37: PKT SEARGING & BOTTOM SERGING*4 | C37: CHOMPA | D37: OL4T | E37: 1 | F37: 200
A39: =+A35+1 -> 16 | B39: =IFERROR(INDEX(OB!B:B,MATCH('BIHOURLY '!A:A,OB!A:A,0)),"") -> SHADOW STITCH POCKET MOUTH & CUT NOTCH | C39: SHAHIDA | D39: =IFERROR(INDEX(OB!G:G,MATCH('BIHOURLY '!A:A,OB!A:A,0)),"") -> SNLS | E39: =IFERROR(INDEX(OB!K:K,MATCH('BIHOURLY '!A:A,OB!A:A,0)),"") -> 1 | F39: 200
B41: PKT MOUTH IRON | C41: RAPIN | D41: IRON TABLE | E41: 1 | F41: 200
A43: =+A39+1 -> 17 | B43: =IFERROR(INDEX(OB!B:B,MATCH('BIHOURLY '!A:A,OB!A:A,0)),"") -> TACK INNER POCKET BAG | C43: RUKSHANA | D43: =IFERROR(INDEX(OB!G:G,MATCH('BIHOURLY '!A:A,OB!A:A,0)),"") -> SNLS | E43: =IFERROR(INDEX(OB!K:K,MATCH('BIHOURLY '!A:A,OB!A:A,0)),"") -> 1 | F43: 200
A45: =+A43+1 -> 18 | B45: CLOSE PKT BAG & BOTTO PRE OL | C45: MILA | D45: =IFERROR(INDEX(OB!G:G,MATCH('BIHOURLY '!A:A,OB!A:A,0)),"") -> OL4T | E45: =IFERROR(INDEX(OB!K:K,MATCH('BIHOURLY '!A:A,OB!A:A,0)),"") -> 1 | F45: 200
A47: =+A45+1 -> 19 | B47: =IFERROR(INDEX(OB!B:B,MATCH('BIHOURLY '!A:A,OB!A:A,0)),"") -> POCKET BAG SIDE WAIST TACK | C47: SHILA | D47: =IFERROR(INDEX(OB!G:G,MATCH('BIHOURLY '!A:A,OB!A:A,0)),"") -> SNLS | E47: 1 | F47: 200
A49: =+A47+1 -> 20 | B49: BOTTOM FOLD & IRON | C49: JAHANARA | D49: IRON TABLE | E49: 1 | F49: 200
A51: =+A49+1 -> 21 | B51: =IFERROR(INDEX(OB!B:B,MATCH('BIHOURLY '!A:A,OB!A:A,0)),"") -> JOIN FRONT RISE | D51: =IFERROR(INDEX(OB!G:G,MATCH('BIHOURLY '!A:A,OB!A:A,0)),"") -> OL4T | E51: =IFERROR(INDEX(OB!K:K,MATCH('BIHOURLY '!A:A,OB!A:A,0)),"") -> 0.5 | F51: =IFERROR((OB!$K$3/'BIHOURLY '!E51)/5,"") -> 340
A53: =+A51+1 -> 22 | B53: =IFERROR(INDEX(OB!B:B,MATCH('BIHOURLY '!A:A,OB!A:A,0)),"") -> 0 | D53: =IFERROR(INDEX(OB!G:G,MATCH('BIHOURLY '!A:A,OB!A:A,0)),"") -> 0 | E53: =IFERROR(INDEX(OB!K:K,MATCH('BIHOURLY '!A:A,OB!A:A,0)),"") | F53: =IFERROR((OB!$K$3/'BIHOURLY '!E53)/5,"")
A55: =+A53+1 -> 23 | B55: =IFERROR(INDEX(OB!B:B,MATCH('BIHOURLY '!A:A,OB!A:A,0)),"") -> 0 | D55: =IFERROR(INDEX(OB!G:G,MATCH('BIHOURLY '!A:A,OB!A:A,0)),"") -> 0 | E55: =IFERROR(INDEX(OB!K:K,MATCH('BIHOURLY '!A:A,OB!A:A,0)),"") | F55: =IFERROR((OB!$K$3/'BIHOURLY '!E55)/5,"")
A57: =+A55+1 -> 24 | B57: =IFERROR(INDEX(OB!B:B,MATCH('BIHOURLY '!A:A,OB!A:A,0)),"") -> 0 | D57: =IFERROR(INDEX(OB!G:G,MATCH('BIHOURLY '!A:A,OB!A:A,0)),"") -> 0 | E57: =IFERROR(INDEX(OB!K:K,MATCH('BIHOURLY '!A:A,OB!A:A,0)),"") | F57: =IFERROR((OB!$K$3/'BIHOURLY '!E57)/5,"")
A59: =+A57+1 -> 25 | B59: =IFERROR(INDEX(OB!B:B,MATCH('BIHOURLY '!A:A,OB!A:A,0)),"") -> 0 | D59: =IFERROR(INDEX(OB!G:G,MATCH('BIHOURLY '!A:A,OB!A:A,0)),"") -> 0 | E59: =IFERROR(INDEX(OB!K:K,MATCH('BIHOURLY '!A:A,OB!A:A,0)),"") | F59: =IFERROR((OB!$K$3/'BIHOURLY '!E59)/5,"")
A61: =+A59+1 -> 26 | B61: =IFERROR(INDEX(OB!B:B,MATCH('BIHOURLY '!A:A,OB!A:A,0)),"") -> 0 | D61: =IFERROR(INDEX(OB!G:G,MATCH('BIHOURLY '!A:A,OB!A:A,0)),"") -> 0 | E61: =IFERROR(INDEX(OB!K:K,MATCH('BIHOURLY '!A:A,OB!A:A,0)),"") | F61: =IFERROR((OB!$K$3/'BIHOURLY '!E61)/5,"")
A63: =+A61+1 -> 27 | B63: =IFERROR(INDEX(OB!B:B,MATCH('BIHOURLY '!A:A,OB!A:A,0)),"") -> 0 | D63: =IFERROR(INDEX(OB!G:G,MATCH('BIHOURLY '!A:A,OB!A:A,0)),"") -> 0 | E63: =IFERROR(INDEX(OB!K:K,MATCH('BIHOURLY '!A:A,OB!A:A,0)),"") | F63: =IFERROR((OB!$K$3/'BIHOURLY '!E63)/5,"")
A65: =+A63+1 -> 28 | B65: =IFERROR(INDEX(OB!B:B,MATCH('BIHOURLY '!A:A,OB!A:A,0)),"") -> 0 | D65: =IFERROR(INDEX(OB!G:G,MATCH('BIHOURLY '!A:A,OB!A:A,0)),"") -> 0 | E65: =IFERROR(INDEX(OB!K:K,MATCH('BIHOURLY '!A:A,OB!A:A,0)),"") | F65: =IFERROR((OB!$K$3/'BIHOURLY '!E65)/5,"")
A67: =+A65+1 -> 29 | B67: =IFERROR(INDEX(OB!B:B,MATCH('BIHOURLY '!A:A,OB!A:A,0)),"") -> 0 | D67: =IFERROR(INDEX(OB!G:G,MATCH('BIHOURLY '!A:A,OB!A:A,0)),"") -> 0 | E67: =IFERROR(INDEX(OB!K:K,MATCH('BIHOURLY '!A:A,OB!A:A,0)),"") | F67: =IFERROR((OB!$K$3/'BIHOURLY '!E67)/5,"")
A69: =+A67+1 -> 30 | B69: =IFERROR(INDEX(OB!B:B,MATCH('BIHOURLY '!A:A,OB!A:A,0)),"") -> 0 | D69: =IFERROR(INDEX(OB!G:G,MATCH('BIHOURLY '!A:A,OB!A:A,0)),"") -> 0 | E69: =IFERROR(INDEX(OB!K:K,MATCH('BIHOURLY '!A:A,OB!A:A,0)),"") | F69: =IFERROR((OB!$K$3/'BIHOURLY '!E69)/5,"")
B71: BACK RISE & FRANT RISE OL | C71: ARIF | D71: OL5T | E71: 1 | F71: 200
A73: =+A69+1 -> 31 | B73: =IFERROR(INDEX(OB!B:B,MATCH('BIHOURLY '!A:A,OB!A:A,0)),"") -> TACK FRONT & BACK AT INSEAM FOR LEG ZIPPER | C73: SHAMIN | D73: =IFERROR(INDEX(OB!G:G,MATCH('BIHOURLY '!A:A,OB!A:A,0)),"") -> SNLS | E73: 2 | F73: 100
C74: NASRIN | F74: 100
...

Sheet BIHOURLY  (2)
A1: SIDNEY APPARELS L.L.C. , AQABA
A2: STYLE NO | C2: =+OB!C2 -> S2554MESS651WV | D2: LINE: - S-24 | E2: Bihourly
C3: TARGET: | D3: 1000 | I3: NAME: | K3: wasana
A4: S NO | B4: OPERATION | C4: OPERATOR | D4: M/C | E4: M/P | F4: BI-HRLY TARGET | G4: Op. WIP | H4: 7.3-9.3 | I4: 9.3-11.45 | J4: 11.45-1.45 | K4: 1.45-4 | L4: 4-6.15
A5: 1 | B5: =IFERROR(INDEX(OB!B:B,MATCH('BIHOURLY (2)'!A:A,OB!A:A,0)),"") -> ATTACH THREE STRIPE | D5: =IFERROR(INDEX(OB!G:G,MATCH('BIHOURLY (2)'!A:A,OB!A:A,0)),"") -> KANSAI | E5: 2 | F5: 100
F6: 100
A8: =+A5+1 -> 2 | B8: =IFERROR(INDEX(OB!B:B,MATCH('BIHOURLY (2)'!A:A,OB!A:A,0)),"") -> CHECK & TRIM THREE STRIPE | D8: IRON TABLE | E8: 1 | F8: 200
A10: =+A8+1 -> 3 | B10: =IFERROR(INDEX(OB!B:B,MATCH('BIHOURLY (2)'!A:A,OB!A:A,0)),"") -> JOIN BACK RISE | D10: =IFERROR(INDEX(OB!G:G,MATCH('BIHOURLY (2)'!A:A,OB!A:A,0)),"") -> OL4T | E10: =IFERROR(INDEX(OB!K:K,MATCH('BIHOURLY (2)'!A:A,OB!A:A,0)),"") -> 0.5 | F10: =IFERROR((OB!$K$3/'BIHOURLY (2)'!E10)/5,"") -> 340
A12: =+A10+1 -> 4 | B12: =IFERROR(INDEX(OB!B:B,MATCH('BIHOURLY (2)'!A:A,OB!A:A,0)),"") -> FUSE & CREASE BOTTOM FOR ZIPPER | D12: =IFERROR(INDEX(OB!G:G,MATCH('BIHOURLY (2)'!A:A,OB!A:A,0)),"") -> IRON TABLE | E12: =IFERROR(INDEX(OB!K:K,MATCH('BIHOURLY (2)'!A:A,OB!A:A,0)),"") -> 1.25 | F12: =IFERROR((OB!$K$3/'BIHOURLY (2)'!E12)/5,"") -> 136
A14: =+A12+1 -> 5 | B14: =IFERROR(INDEX(OB!B:B,MATCH('BIHOURLY (2)'!A:A,OB!A:A,0)),"") -> SERGE BOTTOM FOR LEG ZIPPER*2 | D14: =IFERROR(INDEX(OB!G:G,MATCH('BIHOURLY (2)'!A:A,OB!A:A,0)),"") -> OL4T | E14: =IFERROR(INDEX(OB!K:K,MATCH('BIHOURLY (2)'!A:A,OB!A:A,0)),"") -> 0.5 | F14: =IFERROR((OB!$K$3/'BIHOURLY (2)'!E14)/5,"") -> 340
A16: =+A14+1 -> 6 | B16: =IFERROR(INDEX(OB!B:B,MATCH('BIHOURLY (2)'!A:A,OB!A:A,0)),"") -> 0 | D16: =IFERROR(INDEX(OB!G:G,MATCH('BIHOURLY (2)'!A:A,OB!A:A,0)),"") -> 0 | E16: =IFERROR(INDEX(OB!K:K,MATCH('BIHOURLY (2)'!A:A,OB!A:A,0)),"") | F16: =IFERROR((OB!$K$3/'BIHOURLY (2)'!E16)/5,"")
A18: =+A16+1 -> 7 | B18: =IFERROR(INDEX(OB!B:B,MATCH('BIHOURLY (2)'!A:A,OB!A:A,0)),"") -> 0 | D18: =IFERROR(INDEX(OB!G:G,MATCH('BIHOURLY (2)'!A:A,OB!A:A,0)),"") -> 0 | E18: =IFERROR(INDEX(OB!K:K,MATCH('BIHOURLY (2)'!A:A,OB!A:A,0)),"") | F18: =IFERROR((OB!$K$3/'BIHOURLY (2)'!E18)/5,"")
A20: =+A18+1 -> 8 | B20: =IFERROR(INDEX(OB!B:B,MATCH('BIHOURLY (2)'!A:A,OB!A:A,0)),"") -> 0 | D20: =IFERROR(INDEX(OB!G:G,MATCH('BIHOURLY (2)'!A:A,OB!A:A,0)),"") -> 0 | E20: =IFERROR(INDEX(OB!K:K,MATCH('BIHOURLY (2)'!A:A,OB!A:A,0)),"") | F20: =IFERROR((OB!$K$3/'BIHOURLY (2)'!E20)/5,"")
A22: =+A20+1 -> 9 | B22: =IFERROR(INDEX(OB!B:B,MATCH('BIHOURLY (2)'!A:A,OB!A:A,0)),"") -> 0 | D22: =IFERROR(INDEX(OB!G:G,MATCH('BIHOURLY (2)'!A:A,OB!A:A,0)),"") -> 0 | E22: =IFERROR(INDEX(OB!K:K,MATCH('BIHOURLY (2)'!A:A,OB!A:A,0)),"") | F22: =IFERROR((OB!$K$3/'BIHOURLY (2)'!E22)/5,"")
A24: =+A22+1 -> 10 | B24: =IFERROR(INDEX(OB!B:B,MATCH('BIHOURLY (2)'!A:A,OB!A:A,0)),"") -> 0 | D24: =IFERROR(INDEX(OB!G:G,MATCH('BIHOURLY (2)'!A:A,OB!A:A,0)),"") -> 0 | E24: =IFERROR(INDEX(OB!K:K,MATCH('BIHOURLY (2)'!A:A,OB!A:A,0)),"") | F24: =IFERROR((OB!$K$3/'BIHOURLY (2)'!E24)/5,"")
A26: =+A24+1 -> 11 | B26: =IFERROR(INDEX(OB!B:B,MATCH('BIHOURLY (2)'!A:A,OB!A:A,0)),"") -> 0 | D26: =IFERROR(INDEX(OB!G:G,MATCH('BIHOURLY (2)'!A:A,OB!A:A,0)),"") -> 0 | E26: =IFERROR(INDEX(OB!K:K,MATCH('BIHOURLY (2)'!A:A,OB!A:A,0)),"") | F26: =IFERROR((OB!$K$3/'BIHOURLY (2)'!E26)/5,"")
A28: =+A26+1 -> 12 | B28: =IFERROR(INDEX(OB!B:B,MATCH('BIHOURLY (2)'!A:A,OB!A:A,0)),"") -> 0 | D28: =IFERROR(INDEX(OB!G:G,MATCH('BIHOURLY (2)'!A:A,OB!A:A,0)),"") -> 0 | E28: =IFERROR(INDEX(OB!K:K,MATCH('BIHOURLY (2)'!A:A,OB!A:A,0)),"") | F28: =IFERROR((OB!$K$3/'BIHOURLY (2)'!E28)/5,"")
A31: =+A28+1 -> 13 | B31: =IFERROR(INDEX(OB!B:B,MATCH('BIHOURLY (2)'!A:A,OB!A:A,0)),"") -> FUSE & CREASE POCKET MOUTH | D31: =IFERROR(INDEX(OB!G:G,MATCH('BIHOURLY (2)'!A:A,OB!A:A,0)),"") -> IRON TABLE | E31: 1 | F31: 200
A33: =+A31+1 -> 14 | B33: =IFERROR(INDEX(OB!B:B,MATCH('BIHOURLY (2)'!A:A,OB!A:A,0)),"") -> ATTACH FACING TO POCKET BAG*2 | D33: =IFERROR(INDEX(OB!G:G,MATCH('BIHOURLY (2)'!A:A,OB!A:A,0)),"") -> SNLS | E33: 1 | F33: 200
A35: =+A33+1 -> 15 | B35: =IFERROR(INDEX(OB!B:B,MATCH('BIHOURLY (2)'!A:A,OB!A:A,0)),"") -> ATTACH POCKET BAG TO FRONT | D35: =IFERROR(INDEX(OB!G:G,MATCH('BIHOURLY (2)'!A:A,OB!A:A,0)),"") -> SNLS | E35: =IFERROR(INDEX(OB!K:K,MATCH('BIHOURLY (2)'!A:A,OB!A:A,0)),"") -> 1 | F35: 200
B37: PKT SEARGING & BOTTOM SERGING*4 | D37: OL4T | E37: 1 | F37: 200
A39: =+A35+1 -> 16 | B39: =IFERROR(INDEX(OB!B:B,MATCH('BIHOURLY (2)'!A:A,OB!A:A,0)),"") -> SHADOW STITCH POCKET MOUTH & CUT NOTCH | D39: =IFERROR(INDEX(OB!G:G,MATCH('BIHOURLY (2)'!A:A,OB!A:A,0)),"") -> SNLS | E39: =IFERROR(INDEX(OB!K:K,MATCH('BIHOURLY (2)'!A:A,OB!A:A,0)),"") -> 1 | F39: 200
B41: PKT MOUTH IRON | D41: IRON TABLE | E41: 1 | F41: 200
A43: =+A39+1 -> 17 | B43: =IFERROR(INDEX(OB!B:B,MATCH('BIHOURLY (2)'!A:A,OB!A:A,0)),"") -> TACK INNER POCKET BAG | D43: =IFERROR(INDEX(OB!G:G,MATCH('BIHOURLY (2)'!A:A,OB!A:A,0)),"") -> SNLS | E43: =IFERROR(INDEX(OB!K:K,MATCH('BIHOURLY (2)'!A:A,OB!A:A,0)),"") -> 1 | F43: 200
A45: =+A43+1 -> 18 | B45: CLOSE PKT BAG & BOTTO PRE OL | D45: =IFERROR(INDEX(OB!G:G,MATCH('BIHOURLY (2)'!A:A,OB!A:A,0)),"") -> OL4T | E45: =IFERROR(INDEX(OB!K:K,MATCH('BIHOURLY (2)'!A:A,OB!A:A,0)),"") -> 1 | F45: 200
A47: =+A45+1 -> 19 | B47: =IFERROR(INDEX(OB!B:B,MATCH('BIHOURLY (2)'!A:A,OB!A:A,0)),"") -> POCKET BAG SIDE WAIST TACK | D47: =IFERROR(INDEX(OB!G:G,MATCH('BIHOURLY (2)'!A:A,OB!A:A,0)),"") -> SNLS | E47: 1 | F47: 200
A49: =+A47+1 -> 20 | B49: BOTTOM FOLD & IRON | D49: IRON TABLE | E49: 1 | F49: 200
A51: =+A49+1 -> 21 | B51: =IFERROR(INDEX(OB!B:B,MATCH('BIHOURLY (2)'!A:A,OB!A:A,0)),"") -> JOIN FRONT RISE | D51: =IFERROR(INDEX(OB!G:G,MATCH('BIHOURLY (2)'!A:A,OB!A:A,0)),"") -> OL4T | E51: =IFERROR(INDEX(OB!K:K,MATCH('BIHOURLY (2)'!A:A,OB!A:A,0)),"") -> 0.5 | F51: =IFERROR((OB!$K$3/'BIHOURLY (2)'!E51)/5,"") -> 340
A53: =+A51+1 -> 22 | B53: =IFERROR(INDEX(OB!B:B,MATCH('BIHOURLY (2)'!A:A,OB!A:A,0)),"") -> 0 | D53: =IFERROR(INDEX(OB!G:G,MATCH('BIHOURLY (2)'!A:A,OB!A:A,0)),"") -> 0 | E53: =IFERROR(INDEX(OB!K:K,MATCH('BIHOURLY (2)'!A:A,OB!A:A,0)),"") | F53: =IFERROR((OB!$K$3/'BIHOURLY (2)'!E53)/5,"")
A55: =+A53+1 -> 23 | B55: =IFERROR(INDEX(OB!B:B,MATCH('BIHOURLY (2)'!A:A,OB!A:A,0)),"") -> 0 | D55: =IFERROR(INDEX(OB!G:G,MATCH('BIHOURLY (2)'!A:A,OB!A:A,0)),"") -> 0 | E55: =IFERROR(INDEX(OB!K:K,MATCH('BIHOURLY (2)'!A:A,OB!A:A,0)),"") | F55: =IFERROR((OB!$K$3/'BIHOURLY (2)'!E55)/5,"")
A57: =+A55+1 -> 24 | B57: =IFERROR(INDEX(OB!B:B,MATCH('BIHOURLY (2)'!A:A,OB!A:A,0)),"") -> 0 | D57: =IFERROR(INDEX(OB!G:G,MATCH('BIHOURLY (2)'!A:A,OB!A:A,0)),"") -> 0 | E57: =IFERROR(INDEX(OB!K:K,MATCH('BIHOURLY (2)'!A:A,OB!A:A,0)),"") | F57: =IFERROR((OB!$K$3/'BIHOURLY (2)'!E57)/5,"")
A59: =+A57+1 -> 25 | B59: =IFERROR(INDEX(OB!B:B,MATCH('BIHOURLY (2)'!A:A,OB!A:A,0)),"") -> 0 | D59: =IFERROR(INDEX(OB!G:G,MATCH('BIHOURLY (2)'!A:A,OB!A:A,0)),"") -> 0 | E59: =IFERROR(INDEX(OB!K:K,MATCH('BIHOURLY (2)'!A:A,OB!A:A,0)),"") | F59: =IFERROR((OB!$K$3/'BIHOURLY (2)'!E59)/5,"")
A61: =+A59+1 -> 26 | B61: =IFERROR(INDEX(OB!B:B,MATCH('BIHOURLY (2)'!A:A,OB!A:A,0)),"") -> 0 | D61: =IFERROR(INDEX(OB!G:G,MATCH('BIHOURLY (2)'!A:A,OB!A:A,0)),"") -> 0 | E61: =IFERROR(INDEX(OB!K:K,MATCH('BIHOURLY (2)'!A:A,OB!A:A,0)),"") | F61: =IFERROR((OB!$K$3/'BIHOURLY (2)'!E61)/5,"")
A63: =+A61+1 -> 27 | B63: =IFERROR(INDEX(OB!B:B,MATCH('BIHOURLY (2)'!A:A,OB!A:A,0)),"") -> 0 | D63: =IFERROR(INDEX(OB!G:G,MATCH('BIHOURLY (2)'!A:A,OB!A:A,0)),"") -> 0 | E63: =IFERROR(INDEX(OB!K:K,MATCH('BIHOURLY (2)'!A:A,OB!A:A,0)),"") | F63: =IFERROR((OB!$K$3/'BIHOURLY (2)'!E63)/5,"")
A65: =+A63+1 -> 28 | B65: =IFERROR(INDEX(OB!B:B,MATCH('BIHOURLY (2)'!A:A,OB!A:A,0)),"") -> 0 | D65: =IFERROR(INDEX(OB!G:G,MATCH('BIHOURLY (2)'!A:A,OB!A:A,0)),"") -> 0 | E65: =IFERROR(INDEX(OB!K:K,MATCH('BIHOURLY (2)'!A:A,OB!A:A,0)),"") | F65: =IFERROR((OB!$K$3/'BIHOURLY (2)'!E65)/5,"")
A67: =+A65+1 -> 29 | B67: =IFERROR(INDEX(OB!B:B,MATCH('BIHOURLY (2)'!A:A,OB!A:A,0)),"") -> 0 | D67: =IFERROR(INDEX(OB!G:G,MATCH('BIHOURLY (2)'!A:A,OB!A:A,0)),"") -> 0 | E67: =IFERROR(INDEX(OB!K:K,MATCH('BIHOURLY (2)'!A:A,OB!A:A,0)),"") | F67: =IFERROR((OB!$K$3/'BIHOURLY (2)'!E67)/5,"")
A69: =+A67+1 -> 30 | B69: =IFERROR(INDEX(OB!B:B,MATCH('BIHOURLY (2)'!A:A,OB!A:A,0)),"") -> 0 | D69: =IFERROR(INDEX(OB!G:G,MATCH('BIHOURLY (2)'!A:A,OB!A:A,0)),"") -> 0 | E69: =IFERROR(INDEX(OB!K:K,MATCH('BIHOURLY (2)'!A:A,OB!A:A,0)),"") | F69: =IFERROR((OB!$K$3/'BIHOURLY (2)'!E69)/5,"")
B71: BACK RISE & FRANT RISE OL | D71: OL5T | E71: 1 | F71: 200
A73: =+A69+1 -> 31 | B73: =IFERROR(INDEX(OB!B:B,MATCH('BIHOURLY (2)'!A:A,OB!A:A,0)),"") -> TACK FRONT & BACK AT INSEAM FOR LEG ZIPPER | D73: =IFERROR(INDEX(OB!G:G,MATCH('BIHOURLY (2)'!A:A,OB!A:A,0)),"") -> SNLS | E73: 2 | F73: 100
F74: 100
...

Sheet MACHINE REQURMENT
A1: MACHINE REQUIREMENT FOR STYLE CHANGE FROM | H1: TO | I1: =+OB!C2 -> S2554MESS651WV | J1: Line No | M1: INPUT DATE | N1: 45698
A2: BACK SECTION | E2: FRONT SECTION | I2: WAISTBAND & ASSEMBLY SECTION | M2: SUMMARY
A3: M/C | B3: =+G1 -> 0 | C3: =+I1 -> S2554MESS651WV | D3: Req | E3: M/C | F3: =+G1 -> 0 | G3: =+I1 -> S2554MESS651WV | H3: Req | I3: M/C | J3: =+G1 -> 0 | K3: =+I1 -> S2554MESS651WV | L3: Req | M3: MACHINE TYPE | N3: Req to start style | O3: Requirement | P3: Remarks
A4: SNLS | C4: =+IFERROR(SUMIF(OB!$G$10:$G$25,'MACHINE REQURMENT'!A4,OB!$J$10:$J$25),"0") -> 0 | D4: =C4-B4 -> 0 | E4: SNLS | G4: =+IFERROR(SUMIF(OB!$G$27:$G$44,'MACHINE REQURMENT'!E4,OB!$J$27:$J$44),"0") -> 5 | H4: =G4-F4 -> 5 | I4: SNLS | K4: =+IFERROR(SUMIF(OB!$G$46:$G$83,'MACHINE REQURMENT'!I4,OB!$J$46:$J$83),"0") -> 16 | L4: =K4-J4 -> 16 | M4: SNLS | N4: =D4+H4+L4 -> 21 | O4: =D4+H4+L4 -> 21 | R4: =C4+G4+K4 -> 21
A5: SNEC | C5: =+IFERROR(SUMIF(OB!$G$10:$G$25,'MACHINE REQURMENT'!A5,OB!$J$10:$J$25),"0") -> 0 | D5: =C5-B5 -> 0 | E5: SNEC | G5: =+IFERROR(SUMIF(OB!$G$27:$G$44,'MACHINE REQURMENT'!E5,OB!$J$27:$J$44),"0") -> 0 | H5: =G5-F5 -> 0 | I5: SNEC | K5: =+IFERROR(SUMIF(OB!$G$46:$G$83,'MACHINE REQURMENT'!I5,OB!$J$46:$J$83),"0") -> 0 | L5: =K5-J5 -> 0 | M5: SNEC | N5: =D5+H5+L5 -> 0 | O5: =D5+H5+L5 -> 0 | R5: =C5+G5+K5 -> 0
A6: APW | C6: =+IFERROR(SUMIF(OB!$G$10:$G$25,'MACHINE REQURMENT'!A6,OB!$J$10:$J$25),"0") -> 0 | D6: =C6-B6 -> 0 | E6: APW | G6: =+IFERROR(SUMIF(OB!$G$27:$G$44,'MACHINE REQURMENT'!E6,OB!$J$27:$J$44),"0") -> 0 | H6: =G6-F6 -> 0 | I6: APW | K6: =+IFERROR(SUMIF(OB!$G$46:$G$83,'MACHINE REQURMENT'!I6,OB!$J$46:$J$83),"0") -> 0 | L6: =K6-J6 -> 0 | M6: APW | N6: =D6+H6+L6 -> 0 | O6: =D6+H6+L6 -> 0 | R6: =C6+G6+K6 -> 0
A7: OL3T | C7: =+IFERROR(SUMIF(OB!$G$10:$G$25,'MACHINE REQURMENT'!A7,OB!$J$10:$J$25),"0") -> 0 | D7: =C7-B7 -> 0 | E7: OL3T | G7: =+IFERROR(SUMIF(OB!$G$27:$G$44,'MACHINE REQURMENT'!E7,OB!$J$27:$J$44),"0") -> 0 | H7: =G7-F7 -> 0 | I7: OL3T | K7: =+IFERROR(SUMIF(OB!$G$46:$G$83,'MACHINE REQURMENT'!I7,OB!$J$46:$J$83),"0") -> 0 | L7: =K7-J7 -> 0 | M7: OL3T | N7: =D7+H7+L7 -> 0 | O7: =D7+H7+L7 -> 0 | R7: =C7+G7+K7 -> 0
A8: OL4T | C8: =+IFERROR(SUMIF(OB!$G$10:$G$25,'MACHINE REQURMENT'!A8,OB!$J$10:$J$25),"0") -> 2 | D8: =C8-B8 -> 2 | E8: OL4T | G8: =+IFERROR(SUMIF(OB!$G$27:$G$44,'MACHINE REQURMENT'!E8,OB!$J$27:$J$44),"0") -> 2 | H8: =G8-F8 -> 2 | I8: OL4T | K8: =+IFERROR(SUMIF(OB!$G$46:$G$83,'MACHINE REQURMENT'!I8,OB!$J$46:$J$83),"0") -> 4 | L8: =K8-J8 -> 4 | M8: OL4T | N8: =D8+H8+L8 -> 8 | O8: =D8+H8+L8 -> 8 | R8: =C8+G8+K8 -> 8
A9: OL5T | C9: =+IFERROR(SUMIF(OB!$G$10:$G$25,'MACHINE REQURMENT'!A9,OB!$J$10:$J$25),"0") -> 0 | D9: =C9-B9 -> 0 | E9: OL5T | G9: =+IFERROR(SUMIF(OB!$G$27:$G$44,'MACHINE REQURMENT'!E9,OB!$J$27:$J$44),"0") -> 0 | H9: =G9-F9 -> 0 | I9: OL5T | K9: =+IFERROR(SUMIF(OB!$G$46:$G$83,'MACHINE REQURMENT'!I9,OB!$J$46:$J$83),"0") -> 0 | L9: =K9-J9 -> 0 | M9: OL5T | N9: =D9+H9+L9 -> 0 | O9: =D9+H9+L9 -> 0 | R9: =C9+G9+K9 -> 0
A10: DNLS | C10: =+IFERROR(SUMIF(OB!$G$10:$G$25,'MACHINE REQURMENT'!A10,OB!$J$10:$J$25),"0") -> 0 | D10: =C10-B10 -> 0 | E10: DNLS | G10: =+IFERROR(SUMIF(OB!$G$27:$G$44,'MACHINE REQURMENT'!E10,OB!$J$27:$J$44),"0") -> 0 | H10: =G10-F10 -> 0 | I10: DNLS | K10: =+IFERROR(SUMIF(OB!$G$46:$G$83,'MACHINE REQURMENT'!I10,OB!$J$46:$J$83),"0") -> 0 | L10: =K10-J10 -> 0 | M10: DNLS | N10: =D10+H10+L10 -> 0 | O10: =D10+H10+L10 -> 0 | R10: =C10+G10+K10 -> 0
A11: SNCS | C11: =+IFERROR(SUMIF(OB!$G$10:$G$25,'MACHINE REQURMENT'!A11,OB!$J$10:$J$25),"0") -> 0 | D11: =C11-B11 -> 0 | E11: SNCS | G11: =+IFERROR(SUMIF(OB!$G$27:$G$44,'MACHINE REQURMENT'!E11,OB!$J$27:$J$44),"0") -> 0 | H11: =G11-F11 -> 0 | I11: SNCS | K11: =+IFERROR(SUMIF(OB!$G$46:$G$83,'MACHINE REQURMENT'!I11,OB!$J$46:$J$83),"0") -> 0 | L11: =K11-J11 -> 0 | M11: SNCS | N11: =D11+H11+L11 -> 0 | O11: =D11+H11+L11 -> 0 | R11: =C11+G11+K11 -> 0
A12: DNCS | C12: =+IFERROR(SUMIF(OB!$G$10:$G$25,'MACHINE REQURMENT'!A12,OB!$J$10:$J$25),"0") -> 0 | D12: =C12-B12 -> 0 | E12: DNCS | G12: =+IFERROR(SUMIF(OB!$G$27:$G$44,'MACHINE REQURMENT'!E12,OB!$J$27:$J$44),"0") -> 0 | H12: =G12-F12 -> 0 | I12: DNCS | K12: =+IFERROR(SUMIF(OB!$G$46:$G$83,'MACHINE REQURMENT'!I12,OB!$J$46:$J$83),"0") -> 0 | L12: =K12-J12 -> 0 | M12: DNCS | N12: =D12+H12+L12 -> 0 | O12: =D12+H12+L12 -> 0 | R12: =C12+G12+K12 -> 0
A13: KANSAI | C13: =+IFERROR(SUMIF(OB!$G$10:$G$25,'MACHINE REQURMENT'!A13,OB!$J$10:$J$25),"0") -> 2 | D13: =C13-B13 -> 2 | E13: KANSAI | G13: =+IFERROR(SUMIF(OB!$G$27:$G$44,'MACHINE REQURMENT'!E13,OB!$J$27:$J$44),"0") -> 0 | H13: =G13-F13 -> 0 | I13: KANSAI | K13: =+IFERROR(SUMIF(OB!$G$46:$G$83,'MACHINE REQURMENT'!I13,OB!$J$46:$J$83),"0") -> 1 | L13: =K13-J13 -> 1 | M13: KANSAI | N13: =D13+H13+L13 -> 3 | O13: =D13+H13+L13 -> 3 | R13: =C13+G13+K13 -> 3
A14: BRTK | C14: =+IFERROR(SUMIF(OB!$G$10:$G$25,'MACHINE REQURMENT'!A14,OB!$J$10:$J$25),"0") -> 0 | D14: =C14-B14 -> 0 | E14: BRTK | G14: =+IFERROR(SUMIF(OB!$G$27:$G$44,'MACHINE REQURMENT'!E14,OB!$J$27:$J$44),"0") -> 1 | H14: =G14-F14 -> 1 | I14: BRTK | K14: =+IFERROR(SUMIF(OB!$G$46:$G$83,'MACHINE REQURMENT'!I14,OB!$J$46:$J$83),"0") -> 2 | L14: =K14-J14 -> 2 | M14: BRTK | N14: =D14+H14+L14 -> 3 | O14: =D14+H14+L14 -> 3 | R14: =C14+G14+K14 -> 3
A15: KEYHOLE | C15: =+IFERROR(SUMIF(OB!$G$10:$G$25,'MACHINE REQURMENT'!A15,OB!$J$10:$J$25),"0") -> 0 | D15: =C15-B15 -> 0 | E15: KEYHOLE | G15: =+IFERROR(SUMIF(OB!$G$27:$G$44,'MACHINE REQURMENT'!E15,OB!$J$27:$J$44),"0") -> 0 | H15: =G15-F15 -> 0 | I15: KEYHOLE | K15: =+IFERROR(SUMIF(OB!$G$46:$G$83,'MACHINE REQURMENT'!I15,OB!$J$46:$J$83),"0") -> 0 | L15: =K15-J15 -> 0 | M15: KEYHOLE | N15: =D15+H15+L15 -> 0 | O15: =D15+H15+L15 -> 0 | R15: =C15+G15+K15 -> 0
... A21: BLIND HEM | C21: =+IFERROR(SUMIF(OB!$G$10:$G$25,'MACHINE REQURMENT'!A21,OB!$J$10:$J$25),"0") -> 0 | D21: =C21-B21 -> 0 | E21: BLIND HEM | G21: =+IFERROR(SUMIF(OB!$G$27:$G$44,'MACHINE REQURMENT'!E21,OB!$J$27:$J$44),"0") -> 0 | H21: =G21-F21 -> 0 | I21: BLIND HEM | K21: =+IFERROR(SUMIF(OB!$G$46:$G$83,'MACHINE REQURMENT'!I21,OB!$J$46:$J$83),"0") -> 0 | L21: =K21-J21 -> 0 | M21: BLIND HEM | N21: =D21+H21+L21 -> 0 | O21: =D21+H21+L21 -> 0 | R21: =C21+G21+K21 -> 0
A22: FL2T-FB | C22: =+IFERROR(SUMIF(OB!$G$10:$G$25,'MACHINE REQURMENT'!A22,OB!$J$10:$J$25),"0") -> 0 | D22: =C22-B22 -> 0 | E22: FL2T-FB | G22: =+IFERROR(SUMIF(OB!$G$27:$G$44,'MACHINE REQURMENT'!E22,OB!$J$27:$J$44),"0") -> 0 | H22: =G22-F22 -> 0 | I22: FL2T-FB | K22: =+IFERROR(SUMIF(OB!$G$46:$G$83,'MACHINE REQURMENT'!I22,OB!$J$46:$J$83),"0") -> 0 | L22: =K22-J22 -> 0 | M22: FL2T-FB | N22: =D22+H22+L22 -> 0 | O22: 0 | R22: =C22+G22+K22 -> 0
A23: FL3T-FB | C23: =+IFERROR(SUMIF(OB!$G$10:$G$25,'MACHINE REQURMENT'!A23,OB!$J$10:$J$25),"0") -> 0 | D23: =C23-B23 -> 0 | E23: FL3T-FB | G23: =+IFERROR(SUMIF(OB!$G$27:$G$44,'MACHINE REQURMENT'!E23,OB!$J$27:$J$44),"0") -> 0 | H23: =G23-F23 -> 0 | I23: FL3T-FB | K23: =+IFERROR(SUMIF(OB!$G$46:$G$83,'MACHINE REQURMENT'!I23,OB!$J$46:$J$83),"0") -> 0 | L23: =K23-J23 -> 0 | M23: FL3T-FB | N23: =D23+H23+L23 -> 0 | O23: =D23+H23+L23 -> 0 | R23: =C23+G23+K23 -> 0
A24: FL4T-FB | C24: =+IFERROR(SUMIF(OB!$G$10:$G$25,'MACHINE REQURMENT'!A24,OB!$J$10:$J$25),"0") -> 0 | D24: =C24-B24 -> 0 | E24: FL4T-FB | G24: =+IFERROR(SUMIF(OB!$G$27:$G$44,'MACHINE REQURMENT'!E24,OB!$J$27:$J$44),"0") -> 0 | H24: =G24-F24 -> 0 | I24: FL4T-FB | K24: =+IFERROR(SUMIF(OB!$G$46:$G$83,'MACHINE REQURMENT'!I24,OB!$J$46:$J$83),"0") -> 0 | L24: =K24-J24 -> 0 | M24: FL4T-FB | N24: =D24+H24+L24 -> 0 | O24: =D24+H24+L24 -> 0 | R24: =C24+G24+K24 -> 0
A25: FL5T-FB | C25: =+IFERROR(SUMIF(OB!$G$10:$G$25,'MACHINE REQURMENT'!A25,OB!$J$10:$J$25),"0") -> 0 | D25: =C25-B25 -> 0 | E25: FL5T-FB | G25: =+IFERROR(SUMIF(OB!$G$27:$G$44,'MACHINE REQURMENT'!E25,OB!$J$27:$J$44),"0") -> 0 | H25: =G25-F25 -> 0 | I25: FL5T-FB | K25: =+IFERROR(SUMIF(OB!$G$46:$G$83,'MACHINE REQURMENT'!I25,OB!$J$46:$J$83),"0") -> 0 | L25: =K25-J25 -> 0 | M25: FL5T-FB | N25: =D25+H25+L25 -> 0 | O25: =D25+H25+L25 -> 0 | Q25: =B25+F25+J25 -> 0 | R25: =C25+G25+K25 -> 0
A26: FL6T-FB | C26: =+IFERROR(SUMIF(OB!$G$10:$G$25,'MACHINE REQURMENT'!A26,OB!$J$10:$J$25),"0") -> 0 | D26: =C26-B26 -> 0 | E26: FL6T-FB | G26: =+IFERROR(SUMIF(OB!$G$27:$G$44,'MACHINE REQURMENT'!E26,OB!$J$27:$J$44),"0") -> 0 | H26: =G26-F26 -> 0 | I26: FL6T-FB | K26: =+IFERROR(SUMIF(OB!$G$46:$G$83,'MACHINE REQURMENT'!I26,OB!$J$46:$J$83),"0") -> 0 | L26: =K26-J26 -> 0 | M26: FL6T-FB | N26: =D26+H26+L26 -> 0 | O26: =D26+H26+L26 -> 0 | Q26: =B26+F26+J26 -> 0 | R26: =C26+G26+K26 -> 0
A27: FL2T-CB | C27: =+IFERROR(SUMIF(OB!$G$10:$G$25,'MACHINE REQURMENT'!A27,OB!$J$10:$J$25),"0") -> 0 | D27: =C27-B27 -> 0 | E27: FL2T-CB | G27: =+IFERROR(SUMIF(OB!$G$27:$G$44,'MACHINE REQURMENT'!E27,OB!$J$27:$J$44),"0") -> 0 | H27: =G27-F27 -> 0 | I27: FL2T-CB | K27: =+IFERROR(SUMIF(OB!$G$46:$G$83,'MACHINE REQURMENT'!I27,OB!$J$46:$J$83),"0") -> 0 | L27: =K27-J27 -> 0 | M27: FL2T-CB | N27: =D27+H27+L27 -> 0 | O27: =D27+H27+L27 -> 0 | Q27: =B27+F27+J27 -> 0 | R27: =C27+G27+K27 -> 0
